Workbook

Sheet Daily Report & WIP
S1: AREA BANJARMASIN
H2: SELLING OUT BY MTD | K2: SELLING OUT BY MONTH | N2: SELLING OUT BY VALUE | S2: NURUL (JOINT DATE 1 Juli 2026) | X2: KHORUNISA (JOINT DATE 4 MEI 2026) | AC2: HERLISA (JOINT DATE 2 Desember 2025) | AH2: NUR (JOINT PER TANGGAL 14 AGUSTUS 2026)
A3: REGION | B3: AREA | C3: NAMA TOKO | E3: NAMA SPG | F3: JOINT DATE | G3: HK | H3: TARGET BY HK | I3: ACTUAL BY HK | J3: ACV BY HK (%) | K3: TARGET BY MONTH | L3: ACTUAL BY MONTH | M3: ACV BY MONTH (%) | N3: TOTAL VALUE (Rp) | O3: AVRG PER DAY | S3: Tanggal | T3: STATUS ABSENSI | U3: Selling (pcs) | V3: Value (Rp) | X3: Tanggal | Y3: STATUS ABSENSI | Z3: Selling (pcs) | AA3: Value (Rp) | AC3: Tanggal | AD3: STATUS ABSENSI | AE3: Selling (pcs) | AF3: Value (Rp) | AH3: Tanggal | AI3: STATUS ABSENSI | AJ3: Selling (pcs) | AK3: Value (Rp) | AM3: WIP DI BULAN AGUSTUS 1-31 (UPDATE DATA 1-17 AGUSTUS 2026)
S4: 46235 | T4: 1 | U4: 72 | V4: 432000 | X4: 46235 | Y4: 1 | Z4: 48 | AA4: 288000 | AC4: 46235 | AD4: 1 | AE4: 120 | AF4: 720000 | AH4: 46204 | AJ4: 24 | AK4: 168000 | AM4: AREA | AN4: NAMA | AO4: TARGET BY HK | AP4: ACTUAL BY HK | AQ4: ACCH BY ACTUAL (%) | AR4: ACH | AV4: AVERAGE | AZ4: TARGET BY MONTH | BA4: ACTUAL BY MONTH | BB4: ACCHV BY MONTH (%) | BC4: SELLING BY VALUE (Rp) | BD4: AVRG PER DAY | BE4: RATIO | BF4: GAJI ACTUAL BY HK | BG4: GAJI BY HK | BH4: GAP KARTON PER DAY | BI4: GAP CAN PER DAY | BJ4: TARGET VALUE | BK4: NEEDS VALUE | BL4: GAP RATIO | BM4: KOMITMEN RATIO | BN4: TARGET PER CAN 100% | BO4: TARGET PER KARTON 100% | BP4: TARGET 100% | BQ4: SISA 100% | BR4: SISA KARTON KE 100% | BS4: Joint Date
A5: 4 | B5: Banjarmasin | C5: Farez Barokah | E5: Nurul Agatha | F5: 1 Juli 2026 | G5: =SUM(T4:T34) -> 12 | H5: =G5*120 -> 1440 | I5: =SUM(U4:U34) -> 816 | J5: =I5/H5 -> 0.56666667 | K5: 3240 | L5: =SUM(I5) -> 816 | M5: =L5/K5 -> 0.25185185 | N5: =SUM(V4:V33) -> 4896000 | O5: =L5/G5 -> 68 | S5: 46236 | T5: OFF | X5: 46236 | Y5: OFF | AC5: 46236 | AD5: OFF | AH5: 46205 | AR5: W1 | AS5: W2 | AT5: W3 | AU5: W4 | AV5: W1 | AW5: W2 | AX5: W3 | AY5: W4
A6: 4 | B6: Banjarmasin | C6: yeyen/ibak | E6: Herlisa | F6: 2 Desember 2025 | G6: =SUM(AD4:AD33) -> 13 | H6: =G6*120 -> 1560 | I6: =SUM(AE4:AE33) -> 1272 | J6: =I6/H6 -> 0.81538462 | K6: 3240 | L6: =SUM(I6) -> 1272 | M6: =L6/K6 -> 0.39259259 | N6: =SUM(AF4:AF33) -> 7632000 | O6: =L6/G6 -> 97.846154 | S6: 46237 | T6: IZIN | X6: 46237 | Y6: 1 | Z6: 120 | AA6: 720000 | AC6: 46237 | AD6: 1 | AE6: 96 | AF6: 576000 | AH6: 46206 | AJ6: 24 | AK6: 144000 | AM6: BANJARMASIN | AN6: Nurul | AO6: 24 | AP6: =COUNTIF(T4:T34,1) -> 12 | AQ6: =IFERROR(AP6/AO6,0) -> 0.5 | AR6: =SUM(U4:U10) -> 312 | AS6: =SUM(U11:U17) -> 432 | AT6: =SUM(U18:U24) -> 72 | AU6: =SUM(U25:U34) -> 0 | AV6: =IFERROR(SUM(U4:U10)/COUNTIF(T4:T10,1),0) -> 62.4 | AW6: =IFERROR(SUM(U11:U17)/COUNTIF(T11:T17,1),0) -> 72 | AX6: =IFERROR(SUM(U18:U24)/COUNTIF(T18:T24,1),0) -> 72 | AY6: =IFERROR(SUM(U25:U34)/COUNTIF(T25:T34,1),0) -> 0 | AZ6: =3240 -> 3240 | BA6: =SUM(U4:U34) -> 816 | BB6: =IFERROR(BA6/AZ6,0) -> 0.25185185 | BC6: =SUM(V4:V34) -> 4896000 | BD6: =IFERROR(BA6/AP6,0) -> 68 | BE6: =IFERROR(BF6/BC6,0) -> 0.41607843 | BF6: =BG6*AP6 -> 2037120 | BG6: 169760 | BH6: =IFERROR(MAX(AZ6-BA6,0)/24/MAX(AO6-AP6,1),0) -> 8.4166667 | BI6: =IFERROR(MAX(AZ6-BA6,0)/MAX(AO6-AP6,1),0) -> 202 | BJ6: =IFERROR(26*BG6/BM6,0) -> 16347259 | BK6: =MAX(BJ6-BC6,0) -> 11451259 | BL6: =BE6-BM6 -> 0.14607843 | BM6: 0.27 | BN6: =IFERROR(MAX(BP6-BA6,0)/MAX(AO6-AP6,1),0) -> 202 | BO6: =BN6/24 -> 8.4166667 | BP6: =3240 -> 3240 | BQ6: =MAX(BP6-BA6,0) -> 2424 | BR6: =BQ6/24 -> 101 | BS6: 46204
A7: 4 | B7: Banjarmasin | C7: Saniah | E7: Khoirunisa | F7: 4 Mei 2026 | G7: =SUM(Y4:Y34) -> 12 | H7: =G7*120 -> 1440 | I7: =SUM(Z4:Z33) -> 1536 | J7: =I7/H7 -> 1.0666667 | K7: 3240 | L7: =SUM(I7) -> 1536 | M7: =L7/K7 -> 0.47407407 | N7: =SUM(AA4:AA33) -> 9196000 | O7: =L7/G7 -> 128 | S7: 46238 | T7: 1 | U7: 72 | V7: 432000 | X7: 46238 | Y7: 1 | Z7: 168 | AA7: 1008000 | AC7: 46238 | AD7: 1 | AE7: 168 | AF7: 1008000 | AH7: 46207 | AJ7: 24 | AK7: 144000 | AN7: Khoirunisa | AO7: 24 | AP7: =COUNTIF(Y4:Y34,1) -> 12 | AQ7: =IFERROR(AP7/AO7,0) -> 0.5 | AR7: =SUM(Z4:Z10) -> 888 | AS7: =SUM(Z11:Z17) -> 456 | AT7: =SUM(Z18:Z24) -> 192 | AU7: =SUM(Z25:Z34) -> 0 | AV7: =IFERROR(SUM(Z4:Z10)/COUNTIF(Y4:Y10,1),0) -> 148 | AW7: =IFERROR(SUM(Z11:Z17)/COUNTIF(Y11:Y17,1),0) -> 114 | AX7: =IFERROR(SUM(Z18:Z24)/COUNTIF(Y18:Y24,1),0) -> 96 | AY7: =IFERROR(SUM(Z25:Z34)/COUNTIF(Y25:Y34,1),0) -> 0 | AZ7: =3240 -> 3240 | BA7: =SUM(Z4:Z34) -> 1536 | BB7: =IFERROR(BA7/AZ7,0) -> 0.47407407 | BC7: =SUM(AA4:AA34) -> 9196000 | BD7: =IFERROR(BA7/AP7,0) -> 128 | BE7: =IFERROR(BF7/BC7,0) -> 0.2215224 | BF7: =BG7*AP7 -> 2037120 | BG7: 169760 | BH7: =IFERROR(MAX(AZ7-BA7,0)/24/MAX(AO7-AP7,1),0) -> 5.9166667 | BI7: =IFERROR(MAX(AZ7-BA7,0)/MAX(AO7-AP7,1),0) -> 142 | BJ7: =IFERROR(26*BG7/BM7,0) -> 16347259 | BK7: =MAX(BJ7-BC7,0) -> 7151259.3 | BL7: =BE7-BM7 -> -0.048477599 | BM7: 0.27 | BN7: =IFERROR(MAX(BP7-BA7,0)/MAX(AO7-AP7,1),0) -> 142 | BO7: =BN7/24 -> 5.9166667 | BP7: =3240 -> 3240 | BQ7: =MAX(BP7-BA7,0) -> 1704 | BR7: =BQ7/24 -> 71 | BS7: 46146
A8: 4 | B8: Banjarmasin | C8: Toko Ahim | E8: Nur | F8: 2 Juni 2026 | G8: =SUM(AI4:AI34) -> 2 | H8: =G8*120 -> 240 | I8: =SUM(AJ4:AJ33) -> 396 | J8: =I8/H8 -> 1.65 | K8: 3240 | L8: =SUM(I8) -> 396 | M8: =L8/K8 -> 0.12222222 | N8: =SUM(AK4:AK33) -> 2400000 | O8: =L8/G8 -> 198 | S8: 46239 | T8: 1 | U8: 48 | V8: 288000 | X8: 46239 | Y8: 1 | Z8: 192 | AA8: 1152000 | AC8: 46239 | AD8: 1 | AE8: 96 | AF8: 576000 | AH8: 46208 | AJ8: 48 | AK8: 288000 | AN8: Herlisa | AO8: 24 | AP8: =COUNTIF(AD4:AD34,1) -> 13 | AQ8: =IFERROR(AP8/AO8,0) -> 0.54166667 | AR8: =SUM(AE4:AE10) -> 648 | AS8: =SUM(AE11:AE17) -> 528 | AT8: =SUM(AE18:AE24) -> 96 | AU8: =SUM(AE25:AE34) -> 0 | AV8: =IFERROR(SUM(AE4:AE10)/COUNTIF(AD4:AD10,1),0) -> 108 | AW8: =IFERROR(SUM(AE11:AE17)/COUNTIF(AD11:AD17,1),0) -> 88 | AX8: =IFERROR(SUM(AE18:AE24)/COUNTIF(AD18:AD24,1),0) -> 96 | AY8: =IFERROR(SUM(AE25:AE34)/COUNTIF(AD25:AD34,1),0) -> 0 | AZ8: =3240 -> 3240 | BA8: =SUM(AE4:AE34) -> 1272 | BB8: =IFERROR(BA8/AZ8,0) -> 0.39259259 | BC8: =SUM(AF4:AF34) -> 7632000 | BD8: =IFERROR(BA8/AP8,0) -> 97.846154 | BE8: =IFERROR(BF8/BC8,0) -> 0.28916143 | BF8: =BG8*AP8 -> 2206880 | BG8: 169760 | BH8: =IFERROR(MAX(AZ8-BA8,0)/24/MAX(AO8-AP8,1),0) -> 7.4545455 | BI8: =IFERROR(MAX(AZ8-BA8,0)/MAX(AO8-AP8,1),0) -> 178.90909 | BJ8: =IFERROR(26*BG8/BM8,0) -> 16347259 | BK8: =MAX(BJ8-BC8,0) -> 8715259.3 | BL8: =BE8-BM8 -> 0.019161426 | BM8: 0.27 | BN8: =IFERROR(MAX(BP8-BA8,0)/MAX(AO8-AP8,1),0) -> 178.90909 | BO8: =BN8/24 -> 7.4545455 | BP8: =3240 -> 3240 | BQ8: =MAX(BP8-BA8,0) -> 1968 | BR8: =BQ8/24 -> 82 | BS8: 45993
A9: TOTAL BANJARMASIN | G9: =SUM(G5:G8) -> 39 | H9: =SUM(H5:H8) -> 4680 | I9: =SUM(I5:I8) -> 4020 | J9: =I9/H9 -> 0.85897436 | K9: =SUM(K5:K8) -> 12960 | L9: =SUM(L5:L8) -> 4020 | M9: =L9/K9 -> 0.31018519 | N9: =SUM(N5:N8) -> 24124000 | O9: =I9/G9 -> 103.07692 | S9: 46240 | T9: 1 | U9: 72 | V9: 432000 | X9: 46240 | Y9: 1 | Z9: 216 | AA9: 1296000 | AC9: 46240 | AD9: 1 | AE9: 96 | AF9: 576000 | AH9: 46209 | AJ9: 36 | AK9: 216000 | AN9: Nur | AO9: 24 | AP9: =COUNTIF(AI4:AI34,1) -> 2 | AQ9: =IFERROR(AP9/AO9,0) -> 0.083333333 | AR9: =SUM(AJ4:AJ10) -> 252 | AS9: =SUM(AJ11:AJ17) -> 72 | AT9: =SUM(AJ18:AJ24) -> 72 | AU9: =SUM(AJ25:AJ34) -> 0 | AV9: =IFERROR(SUM(AJ4:AJ10)/COUNTIF(AI4:AI10,1),0) -> 0 | AW9: =IFERROR(SUM(AJ11:AJ17)/COUNTIF(AI11:AI17,1),0) -> 72 | AX9: =IFERROR(SUM(AJ18:AJ24)/COUNTIF(AI18:AI24,1),0) -> 72 | AY9: =IFERROR(SUM(AJ25:AJ34)/COUNTIF(AI25:AI34,1),0) -> 0 | AZ9: =3240 -> 3240 | BA9: =SUM(AJ4:AJ34) -> 396 | BB9: =IFERROR(BA9/AZ9,0) -> 0.12222222 | BC9: =SUM(AK4:AK34) -> 2400000 | BD9: =IFERROR(BA9/AP9,0) -> 198 | BE9: =IFERROR(BF9/BC9,0) -> 0.14146667 | BF9: =BG9*AP9 -> 339520 | BG9: 169760 | BH9: =IFERROR(MAX(AZ9-BA9,0)/24/MAX(AO9-AP9,1),0) -> 5.3863636 | BI9: =IFERROR(MAX(AZ9-BA9,0)/MAX(AO9-AP9,1),0) -> 129.27273 | BJ9: =IFERROR(26*BG9/BM9,0) -> 16347259 | BK9: =MAX(BJ9-BC9,0) -> 13947259 | BL9: =BE9-BM9 -> -0.12853333 | BM9: 0.27 | BN9: =IFERROR(MAX(BP9-BA9,0)/MAX(AO9-AP9,1),0) -> 129.27273 | BO9: =BN9/24 -> 5.3863636 | BP9: =3240 -> 3240 | BQ9: =MAX(BP9-BA9,0) -> 2844 | BR9: =BQ9/24 -> 118.5 | BS9: 46248
S10: 46241 | T10: 1 | U10: 48 | V10: 288000 | X10: 46241 | Y10: 1 | Z10: 144 | AA10: 864000 | AC10: 46241 | AD10: 1 | AE10: 72 | AF10: 432000 | AH10: 46210 | AJ10: 96 | AK10: 576000 | AM10: GRAND TOTAL BANJARMASIN | AO10: =SUM(AO6:AO9) -> 96 | AP10: =SUM(AP6:AP9) -> 39 | AQ10: =IFERROR(AP10/AO10,0) -> 0.40625 | AR10: =SUM(AR6:AR9) -> 2100 | AS10: =SUM(AS6:AS9) -> 1488 | AT10: =SUM(AT6:AT9) -> 432 | AU10: =SUM(AU6:AU9) -> 0 | AV10: =IFERROR(AR10/(COUNTIF(T4:T10,1)+COUNTIF(Y4:Y10,1)+COUNTIF(AD4:AD10,1)+COUNTIF(AI4:AI10,1)),0) -> 123.52941 | AW10: =IFERROR(AS10/(COUNTIF(T11:T17,1)+COUNTIF(Y11:Y17,1)+COUNTIF(AD11:AD17,1)+COUNTIF(AI11:AI17,1)),0) -> 87.529412 | AX10: =IFERROR(AT10/(COUNTIF(T18:T24,1)+COUNTIF(Y18:Y24,1)+COUNTIF(AD18:AD24,1)+COUNTIF(AI18:AI24,1)),0) -> 86.4 | AY10: =IFERROR(AU10/(COUNTIF(T25:T34,1)+COUNTIF(Y25:Y34,1)+COUNTIF(AD25:AD34,1)+COUNTIF(AI25:AI34,1)),0) -> 0 | AZ10: =SUM(AZ6:AZ9) -> 12960 | BA10: =SUM(BA6:BA9) -> 4020 | BB10: =IFERROR(BA10/AZ10,0) -> 0.31018519 | BC10: =SUM(BC6:BC9) -> 24124000 | BD10: =IFERROR(BA10/AP10,0) -> 103.07692 | BE10: =IFERROR(BF10/BC10,0) -> 0.27444205 | BF10: =SUM(BF6:BF9) -> 6620640 | BG10: 169760 | BH10: =IFERROR(MAX(AZ10-BA10,0)/24/MAX(AO10-AP10,1),0) -> 6.5350877 | BI10: =IFERROR(MAX(AZ10-BA10,0)/MAX(AO10-AP10,1),0) -> 156.84211 | BJ10: =SUM(BJ6:BJ9) -> 65389037 | BK10: =MAX(BJ10-BC10,0) -> 41265037 | BL10: =BE10-BM10 -> 0.0044420494 | BM10: 0.27 | BN10: =IFERROR(MAX(BP10-BA10,0)/MAX(AO10-AP10,1),0) -> 156.84211 | BO10: =BN10/24 -> 6.5350877 | BP10: =SUM(BP6:BP9) -> 12960 | BQ10: =MAX(BP10-BA10,0) -> 8940 | BR10: =BQ10/24 -> 372.5
A11: Issue/Insight : | S11: 46242 | T11: 1 | U11: 72 | V11: 432000 | X11: 46242 | Y11: 1 | Z11: 144 | AA11: 864000 | AC11: 46242 | AD11: 1 | AE11: 96 | AF11: 576000 | AH11: 46211 | AJ11: 24 | AK11: 144000 | AM11: BALIKPAPAN | AN11: Grace | AO11: 24 | AP11: =COUNTIF(AD40:AD70,1) -> 13 | AQ11: =IFERROR(AP11/AO11,0) -> 0.54166667 | AR11: =SUM(AE40:AE46) -> 192 | AS11: =SUM(AE47:AE53) -> 240 | AT11: =SUM(AE54:AE60) -> 48 | AU11: =SUM(AE61:AE70) -> 0 | AV11: =IFERROR(SUM(AE40:AE46)/COUNTIF(AD40:AD46,1),0) -> 38.4 | AW11: =IFERROR(SUM(AE47:AE53)/COUNTIF(AD47:AD53,1),0) -> 40 | AX11: =IFERROR(SUM(AE54:AE60)/COUNTIF(AD54:AD60,1),0) -> 24 | AY11: =IFERROR(SUM(AE61:AE70)/COUNTIF(AD61:AD70,1),0) -> 0 | AZ11: =3240 -> 3240 | BA11: =SUM(AE40:AE70) -> 480 | BB11: =IFERROR(BA11/AZ11,0) -> 0.14814815 | BC11: =SUM(AF40:AF70) -> 2894400 | BD11: =IFERROR(BA11/AP11,0) -> 36.923077 | BE11: =IFERROR(BF11/BC11,0) -> 0.76260468 | BF11: =BG11*AP11 -> 2207283 | BG11: 169791 | BH11: =IFERROR(MAX(AZ11-BA11,0)/24/MAX(AO11-AP11,1),0) -> 10.454545 | BI11: =IFERROR(MAX(AZ11-BA11,0)/MAX(AO11-AP11,1),0) -> 250.90909 | BJ11: =IFERROR(26*BG11/BM11,0) -> 14715220 | BK11: =MAX(BJ11-BC11,0) -> 11820820 | BL11: =BE11-BM11 -> 0.46260468 | BM11: 0.3 | BN11: =IFERROR(MAX(BP11-BA11,0)/MAX(AO11-AP11,1),0) -> 250.90909 | BO11: =BN11/24 -> 10.454545 | BP11: =3240 -> 3240 | BQ11: =MAX(BP11-BA11,0) -> 2760 | BR11: =BQ11/24 -> 115 | BS11: 46204
A12: 1. SPG atas nama Herlisa izin | S12: 46243 | T12: OFF | X12: 46243 | Y12: OFF | AC12: 46243 | AD12: OFF | AH12: 46212 | AN12: Rami | AO12: 24 | AP12: =COUNTIF(AI40:AI70,1) -> 14 | AQ12: =IFERROR(AP12/AO12,0) -> 0.58333333 | AR12: =SUM(AJ40:AJ46) -> 240 | AS12: =SUM(AJ47:AJ53) -> 264 | AT12: =SUM(AJ54:AJ60) -> 168 | AU12: =SUM(AJ61:AJ70) -> 0 | AV12: =IFERROR(SUM(AJ40:AJ46)/COUNTIF(AI40:AI46,1),0) -> 48 | AW12: =IFERROR(SUM(AJ47:AJ53)/COUNTIF(AI47:AI53,1),0) -> 44 | AX12: =IFERROR(SUM(AJ54:AJ60)/COUNTIF(AI54:AI60,1),0) -> 56 | AY12: =IFERROR(SUM(AJ61:AJ70)/COUNTIF(AI61:AI70,1),0) -> 0 | AZ12: =3240 -> 3240 | BA12: =SUM(AJ40:AJ70) -> 672 | BB12: =IFERROR(BA12/AZ12,0) -> 0.20740741 | BC12: =SUM(AK40:AK70) -> 3952800 | BD12: =IFERROR(BA12/AP12,0) -> 48 | BE12: =IFERROR(BF12/BC12,0) -> 0.6013646 | BF12: =BG12*AP12 -> 2377074 | BG12: 169791 | BH12: =IFERROR(MAX(AZ12-BA12,0)/24/MAX(AO12-AP12,1),0) -> 10.7 | BI12: =IFERROR(MAX(AZ12-BA12,0)/MAX(AO12-AP12,1),0) -> 256.8 | BJ12: =IFERROR(26*BG12/BM12,0) -> 14715220 | BK12: =MAX(BJ12-BC12,0) -> 10762420 | BL12: =BE12-BM12 -> 0.3013646 | BM12: 0.3 | BN12: =IFERROR(MAX(BP12-BA12,0)/MAX(AO12-AP12,1),0) -> 256.8 | BO12: =BN12/24 -> 10.7 | BP12: =3240 -> 3240 | BQ12: =MAX(BP12-BA12,0) -> 2568 | BR12: =BQ12/24 -> 107 | BS12: 46174
A13: 2. Sebagian Toko/Retailer under grosir masih banyak stock | S13: 46244 | T13: 1 | U13: 72 | V13: 432000 | X13: 46244 | Y13: 1 | Z13: 120 | AA13: 720000 | AC13: 46244 | AD13: 1 | AE13: 96 | AF13: 576000 | AH13: 46213 | AM13: GRAND TOTAL BALIKPAPAN | AO13: =SUM(AO11:AO12) -> 48 | AP13: =SUM(AP11:AP12) -> 27 | AQ13: =IFERROR(AP13/AO13,0) -> 0.5625 | AR13: =SUM(AR11:AR12) -> 432 | AS13: =SUM(AS11:AS12) -> 504 | AT13: =SUM(AT11:AT12) -> 216 | AU13: =SUM(AU11:AU12) -> 0 | AV13: =IFERROR(AR13/(COUNTIF(AD40:AD46,1)+COUNTIF(AI40:AI46,1)),0) -> 43.2 | AW13: =IFERROR(AS13/(COUNTIF(AD47:AD53,1)+COUNTIF(AI47:AI53,1)),0) -> 42 | AX13: =IFERROR(AT13/(COUNTIF(AD54:AD60,1)+COUNTIF(AI54:AI60,1)),0) -> 43.2 | AY13: =IFERROR(AU13/(COUNTIF(AD61:AD70,1)+COUNTIF(AI61:AI70,1)),0) -> 0 | AZ13: =SUM(AZ11:AZ12) -> 6480 | BA13: =SUM(BA11:BA12) -> 1152 | BB13: =IFERROR(BA13/AZ13,0) -> 0.17777778 | BC13: =SUM(BC11:BC12) -> 6847200 | BD13: =IFERROR(BA13/AP13,0) -> 42.666667 | BE13: =IFERROR(BF13/BC13,0) -> 0.66952287 | BF13: =SUM(BF11:BF12) -> 4584357 | BG13: 169791 | BH13: =IFERROR(MAX(AZ13-BA13,0)/24/MAX(AO13-AP13,1),0) -> 10.571429 | BI13: =IFERROR(MAX(AZ13-BA13,0)/MAX(AO13-AP13,1),0) -> 253.71429 | BJ13: =SUM(BJ11:BJ12) -> 29430440 | BK13: =MAX(BJ13-BC13,0) -> 22583240 | BL13: =BE13-BM13 -> 0.36952287 | BM13: 0.3 | BN13: =IFERROR(MAX(BP13-BA13,0)/MAX(AO13-AP13,1),0) -> 253.71429 | BO13: =BN13/24 -> 10.571429 | BP13: =SUM(BP11:BP12) -> 6480 | BQ13: =MAX(BP13-BA13,0) -> 5328 | BR13: =BQ13/24 -> 222
A14: 3. SPG atas nama IKA Resign | S14: 46245 | T14: 1 | U14: 72 | V14: 432000 | X14: 46245 | Y14: IZIN | AC14: 46245 | AD14: 1 | AE14: 96 | AF14: 576000 | AH14: 46214 | AM14: PALANGKARAYA | AN14: Fani Febriani | AO14: 24 | AP14: =COUNTIF(T83:T113,1) -> 14 | AQ14: =IFERROR(AP14/AO14,0) -> 0.58333333 | AR14: =SUM(U83:U89) -> 354 | AS14: =SUM(U90:U96) -> 413 | AT14: =SUM(U97:U103) -> 168 | AU14: =SUM(U104:U113) -> 0 | AV14: =IFERROR(SUM(U83:U89)/COUNTIF(T83:T89,1),0) -> 59 | AW14: =IFERROR(SUM(U90:U96)/COUNTIF(T90:T96,1),0) -> 68.833333 | AX14: =IFERROR(SUM(U97:U103)/COUNTIF(T97:T103,1),0) -> 84 | AY14: =IFERROR(SUM(U104:U113)/COUNTIF(T104:T113,1),0) -> 0 | AZ14: =3240 -> 3240 | BA14: =SUM(U83:U113) -> 935 | BB14: =IFERROR(BA14/AZ14,0) -> 0.28858025 | BC14: =SUM(V83:V113) -> 5368000 | BD14: =IFERROR(BA14/AP14,0) -> 66.785714 | BE14: =IFERROR(BF14/BC14,0) -> 0.42957936 | BF14: =BG14*AP14 -> 2305982 | BG14: 164713 | BH14: =IFERROR(MAX(AZ14-BA14,0)/24/MAX(AO14-AP14,1),0) -> 9.6041667 | BI14: =IFERROR(MAX(AZ14-BA14,0)/MAX(AO14-AP14,1),0) -> 230.5 | BJ14: =IFERROR(26*BG14/BM14,0) -> 15861252 | BK14: =MAX(BJ14-BC14,0) -> 10493252 | BL14: =BE14-BM14 -> 0.15957936 | BM14: 0.27 | BN14: =IFERROR(MAX(BP14-BA14,0)/MAX(AO14-AP14,1),0) -> 230.5 | BO14: =BN14/24 -> 9.6041667 | BP14: =3240 -> 3240 | BQ14: =MAX(BP14-BA14,0) -> 2305 | BR14: =BQ14/24 -> 96.041667 | BS14: 46018
A15: 4. terdapat harga Rp.4.500 di toko di area Banjarmasin tengah | S15: 46246 | T15: 1 | U15: 72 | V15: 432000 | X15: 46246 | Y15: IZIN | AC15: 46246 | AD15: 1 | AE15: 72 | AF15: 432000 | AH15: 46215 | AN15: Siska | AO15: 24 | AP15: =COUNTIF(Y83:Y113,1) -> 14 | AQ15: =IFERROR(AP15/AO15,0) -> 0.58333333 | AR15: =SUM(Z83:Z89) -> 410 | AS15: =SUM(Z90:Z96) -> 466 | AT15: =SUM(Z97:Z103) -> 120 | AU15: =SUM(Z104:Z113) -> 0 | AV15: =IFERROR(SUM(Z83:Z89)/COUNTIF(Y83:Y89,1),0) -> 68.333333 | AW15: =IFERROR(SUM(Z90:Z96)/COUNTIF(Y90:Y96,1),0) -> 77.666667 | AX15: =IFERROR(SUM(Z97:Z103)/COUNTIF(Y97:Y103,1),0) -> 60 | AY15: =IFERROR(SUM(Z104:Z113)/COUNTIF(Y104:Y113,1),0) -> 0 | AZ15: =3240 -> 3240 | BA15: =SUM(Z83:Z113) -> 996 | BB15: =IFERROR(BA15/AZ15,0) -> 0.30740741 | BC15: =SUM(AA83:AA113) -> 5976000 | BD15: =IFERROR(BA15/AP15,0) -> 71.142857 | BE15: =IFERROR(BF15/BC15,0) -> 0.38587383 | BF15: =BG15*AP15 -> 2305982 | BG15: 164713 | BH15: =IFERROR(MAX(AZ15-BA15,0)/24/MAX(AO15-AP15,1),0) -> 9.35 | BI15: =IFERROR(MAX(AZ15-BA15,0)/MAX(AO15-AP15,1),0) -> 224.4 | BJ15: =IFERROR(26*BG15/BM15,0) -> 15861252 | BK15: =MAX(BJ15-BC15,0) -> 9885251.9 | BL15: =BE15-BM15 -> 0.11587383 | BM15: 0.27 | BN15: =IFERROR(MAX(BP15-BA15,0)/MAX(AO15-AP15,1),0) -> 224.4 | BO15: =BN15/24 -> 9.35 | BP15: =3240 -> 3240 | BQ15: =MAX(BP15-BA15,0) -> 2244 | BR15: =BQ15/24 -> 93.5 | BS15: 46120
S16: 46247 | T16: 1 | U16: 72 | V16: 432000 | X16: 46247 | Y16: 1 | Z16: 96 | AA16: 576000 | AC16: 46247 | AD16: 1 | AE16: 96 | AF16: 576000 | AH16: 46216 | AM16: GRAND TOTAL PALANGKARAYA | AO16: =SUM(AO14:AO15) -> 48 | AP16: =SUM(AP14:AP15) -> 28 | AQ16: =IFERROR(AP16/AO16,0) -> 0.58333333 | AR16: =SUM(AR14:AR15) -> 764 | AS16: =SUM(AS14:AS15) -> 879 | AT16: =SUM(AT14:AT15) -> 288 | AU16: =SUM(AU14:AU15) -> 0 | AV16: =IFERROR(AR16/(COUNTIF(T83:T89,1)+COUNTIF(Y83:Y89,1)),0) -> 63.666667 | AW16: =IFERROR(AS16/(COUNTIF(T90:T96,1)+COUNTIF(Y90:Y96,1)),0) -> 73.25 | AX16: =IFERROR(AT16/(COUNTIF(T97:T103,1)+COUNTIF(Y97:Y103,1)),0) -> 72 | AY16: =IFERROR(AU16/(COUNTIF(T104:T113,1)+COUNTIF(Y104:Y113,1)),0) -> 0 | AZ16: =SUM(AZ14:AZ15) -> 6480 | BA16: =SUM(BA14:BA15) -> 1931 | BB16: =IFERROR(BA16/AZ16,0) -> 0.29799383 | BC16: =SUM(BC14:BC15) -> 11344000 | BD16: =IFERROR(BA16/AP16,0) -> 68.964286 | BE16: =IFERROR(BF16/BC16,0) -> 0.40655536 | BF16: =SUM(BF14:BF15) -> 4611964 | BG16: 164713 | BH16: =IFERROR(MAX(AZ16-BA16,0)/24/MAX(AO16-AP16,1),0) -> 9.4770833 | BI16: =IFERROR(MAX(AZ16-BA16,0)/MAX(AO16-AP16,1),0) -> 227.45 | BJ16: =SUM(BJ14:BJ15) -> 31722504 | BK16: =MAX(BJ16-BC16,0) -> 20378504 | BL16: =BE16-BM16 -> 0.13655536 | BM16: 0.27 | BN16: =IFERROR(MAX(BP16-BA16,0)/MAX(AO16-AP16,1),0) -> 227.45 | BO16: =BN16/24 -> 9.4770833 | BP16: =SUM(BP14:BP15) -> 6480 | BQ16: =MAX(BP16-BA16,0) -> 4549 | BR16: =BQ16/24 -> 189.54167
A17: Action Plan: | S17: 46248 | T17: 1 | U17: 72 | V17: 432000 | X17: 46248 | Y17: 1 | Z17: 96 | AA17: 576000 | AC17: 46248 | AD17: 1 | AE17: 72 | AF17: 432000 | AH17: 46217 | AI17: 1 | AJ17: 48 | AK17: 288000 | AM17: SAMARINDA | AN17: Fitriani | AO17: 24 | AP17: =COUNTIF(T40:T70,1) -> 13 | AQ17: =IFERROR(AP17/AO17,0) -> 0.54166667 | AR17: =SUM(U40:U46) -> 240 | AS17: =SUM(U47:U53) -> 456 | AT17: =SUM(U54:U60) -> 168 | AU17: =SUM(U61:U70) -> 0 | AV17: =IFERROR(SUM(U40:U46)/COUNTIF(T40:T46,1),0) -> 48 | AW17: =IFERROR(SUM(U47:U53)/COUNTIF(T47:T53,1),0) -> 76 | AX17: =IFERROR(SUM(U54:U60)/COUNTIF(T54:T60,1),0) -> 84 | AY17: =IFERROR(SUM(U61:U70)/COUNTIF(T61:T70,1),0) -> 0 | AZ17: =3240 -> 3240 | BA17: =SUM(U40:U70) -> 864 | BB17: =IFERROR(BA17/AZ17,0) -> 0.26666667 | BC17: =SUM(V40:V70) -> 5616000 | BD17: =IFERROR(BA17/AP17,0) -> 66.461538 | BE17: =IFERROR(BF17/BC17,0) -> 0.4043588 | BF17: =BG17*AP17 -> 2270879 | BG17: 174683 | BH17: =IFERROR(MAX(AZ17-BA17,0)/24/MAX(AO17-AP17,1),0) -> 9 | BI17: =IFERROR(MAX(AZ17-BA17,0)/MAX(AO17-AP17,1),0) -> 216 | BJ17: =IFERROR(26*BG17/BM17,0) -> 15139193 | BK17: =MAX(BJ17-BC17,0) -> 9523193.3 | BL17: =BE17-BM17 -> 0.1043588 | BM17: 0.3 | BN17: =IFERROR(MAX(BP17-BA17,0)/MAX(AO17-AP17,1),0) -> 216 | BO17: =BN17/24 -> 9 | BP17: =3240 -> 3240 | BQ17: =MAX(BP17-BA17,0) -> 2376 | BR17: =BQ17/24 -> 99 | BS17: 46060
A18: 1. Untuk toko stok masih banyak: jangan push ambil banyak, cukup order kecil 3–6 can + bantu display biar stok lama cepat jalan, lalu follow up H+3. | S18: 46249 | T18: 1 | U18: 72 | V18: 432000 | X18: 46249 | Y18: 1 | Z18: 120 | AA18: 700000 | AC18: 46249 | AD18: 1 | AE18: 96 | AF18: 576000 | AH18: 46218 | AI18: 1 | AJ18: 72 | AK18: 432000 | AN18: Desi Susanti | AO18: 24 | AP18: =COUNTIF(Y40:Y70,1) -> 14 | AQ18: =IFERROR(AP18/AO18,0) -> 0.58333333 | AR18: =SUM(Z40:Z46) -> 312 | AS18: =SUM(Z47:Z53) -> 384 | AT18: =SUM(Z54:Z60) -> 120 | AU18: =SUM(Z61:Z70) -> 0 | AV18: =IFERROR(SUM(Z40:Z46)/COUNTIF(Y40:Y46,1),0) -> 52 | AW18: =IFERROR(SUM(Z47:Z53)/COUNTIF(Y47:Y53,1),0) -> 64 | AX18: =IFERROR(SUM(Z54:Z60)/COUNTIF(Y54:Y60,1),0) -> 60 | AY18: =IFERROR(SUM(Z61:Z70)/COUNTIF(Y61:Y70,1),0) -> 0 | AZ18: =3240 -> 3240 | BA18: =SUM(Z40:Z70) -> 816 | BB18: =IFERROR(BA18/AZ18,0) -> 0.25185185 | BC18: =SUM(AA40:AA70) -> 5112000 | BD18: =IFERROR(BA18/AP18,0) -> 58.285714 | BE18: =IFERROR(BF18/BC18,0) -> 0.47839632 | BF18: =BG18*AP18 -> 2445562 | BG18: 174683 | BH18: =IFERROR(MAX(AZ18-BA18,0)/24/MAX(AO18-AP18,1),0) -> 10.1 | BI18: =IFERROR(MAX(AZ18-BA18,0)/MAX(AO18-AP18,1),0) -> 242.4 | BJ18: =IFERROR(26*BG18/BM18,0) -> 15139193 | BK18: =MAX(BJ18-BC18,0) -> 10027193 | BL18: =BE18-BM18 -> 0.17839632 | BM18: 0.3 | BN18: =IFERROR(MAX(BP18-BA18,0)/MAX(AO18-AP18,1),0) -> 242.4 | BO18: =BN18/24 -> 10.1 | BP18: =3240 -> 3240 | BQ18: =MAX(BP18-BA18,0) -> 2424 | BR18: =BQ18/24 -> 101 | BS18: 46073
A19: 2. SPG fokus edukasi dan sampling saat stay di Outlet | S19: 46250 | T19: OFF | X19: 46250 | Y19: 1 | Z19: 72 | AA19: 432000 | AC19: 46250 | AD19: OFF | AH19: 46219 | AM19: GRAND TOTAL SAMARINDA | AO19: =SUM(AO17:AO18) -> 48 | AP19: =SUM(AP17:AP18) -> 27 | AQ19: =IFERROR(AP19/AO19,0) -> 0.5625 | AR19: =SUM(AR17:AR18) -> 552 | AS19: =SUM(AS17:AS18) -> 840 | AT19: =SUM(AT17:AT18) -> 288 | AU19: =SUM(AU17:AU18) -> 0 | AV19: =IFERROR(AR19/(COUNTIF(T40:T46,1)+COUNTIF(Y40:Y46,1)),0) -> 50.181818 | AW19: =IFERROR(AS19/(COUNTIF(T47:T53,1)+COUNTIF(Y47:Y53,1)),0) -> 70 | AX19: =IFERROR(AT19/(COUNTIF(T54:T60,1)+COUNTIF(Y54:Y60,1)),0) -> 72 | AY19: =IFERROR(AU19/(COUNTIF(T61:T70,1)+COUNTIF(Y61:Y70,1)),0) -> 0 | AZ19: =SUM(AZ17:AZ18) -> 6480 | BA19: =SUM(BA17:BA18) -> 1680 | BB19: =IFERROR(BA19/AZ19,0) -> 0.25925926 | BC19: =SUM(BC17:BC18) -> 10728000 | BD19: =IFERROR(BA19/AP19,0) -> 62.222222 | BE19: =IFERROR(BF19/BC19,0) -> 0.43963842 | BF19: =SUM(BF17:BF18) -> 4716441 | BG19: 174683 | BH19: =IFERROR(MAX(AZ19-BA19,0)/24/MAX(AO19-AP19,1),0) -> 9.5238095 | BI19: =IFERROR(MAX(AZ19-BA19,0)/MAX(AO19-AP19,1),0) -> 228.57143 | BJ19: =SUM(BJ17:BJ18) -> 30278387 | BK19: =MAX(BJ19-BC19,0) -> 19550387 | BL19: =BE19-BM19 -> 0.13963842 | BM19: 0.3 | BN19: =IFERROR(MAX(BP19-BA19,0)/MAX(AO19-AP19,1),0) -> 228.57143 | BO19: =BN19/24 -> 9.5238095 | BP19: =SUM(BP17:BP18) -> 6480 | BQ19: =MAX(BP19-BA19,0) -> 4800 | BR19: =BQ19/24 -> 200
A20: 3. Fokus untuk jalin hubungan dengan toko-toko meminta no wa pihak toko jika dari toko barang masih ada | S20: 46251 | T20: IZIN | X20: 46251 | Y20: LIBUR | AC20: 46251 | AD20: LIBUR | AH20: 46220 | AM20: MAKASSAR | AN20: Amelia | AO20: 24 | AP20: =COUNTIF(T119:T149,1) -> 16 | AQ20: =IFERROR(AP20/AO20,0) -> 0.66666667 | AR20: =SUM(U119:U125) -> 204 | AS20: =SUM(U126:U132) -> 151 | AT20: =SUM(U133:U139) -> 132 | AU20: =SUM(U140:U149) -> 0 | AV20: =IFERROR(SUM(U119:U125)/COUNTIF(T119:T125,1),0) -> 34 | AW20: =IFERROR(SUM(U126:U132)/COUNTIF(T126:T132,1),0) -> 25.166667 | AX20: =IFERROR(SUM(U133:U139)/COUNTIF(T133:T139,1),0) -> 33 | AY20: =IFERROR(SUM(U140:U149)/COUNTIF(T140:T149,1),0) -> 0 | AZ20: =3240 -> 3240 | BA20: =SUM(U119:U149) -> 487 | BB20: =IFERROR(BA20/AZ20,0) -> 0.15030864 | BC20: =SUM(V119:V149) -> 3251000 | BD20: =IFERROR(BA20/AP20,0) -> 30.4375 | BE20: =IFERROR(BF20/BC20,0) -> 0.89081267 | BF20: =BG20*AP20 -> 2896032 | BG20: 181002 | BH20: =IFERROR(MAX(AZ20-BA20,0)/24/MAX(AO20-AP20,1),0) -> 14.338542 | BI20: =IFERROR(MAX(AZ20-BA20,0)/MAX(AO20-AP20,1),0) -> 344.125 | BJ20: =IFERROR(26*BG20/BM20,0) -> 15686840 | BK20: =MAX(BJ20-BC20,0) -> 12435840 | BL20: =BE20-BM20 -> 0.59081267 | BM20: 0.3 | BN20: =IFERROR(MAX(BP20-BA20,0)/MAX(AO20-AP20,1),0) -> 344.125 | BO20: =BN20/24 -> 14.338542 | BP20: =3240 -> 3240 | BQ20: =MAX(BP20-BA20,0) -> 2753 | BR20: =BQ20/24 -> 114.70833 | BS20: 46057
S21: 46252 | X21: 46252 | AC21: 46252 | AH21: 46221 | AN21: Dira/Nadira | AO21: 24 | AP21: =COUNTIF(Y119:Y149,1) -> 13 | AQ21: =IFERROR(AP21/AO21,0) -> 0.54166667 | AR21: =SUM(Z119:Z125) -> 65 | AS21: =SUM(Z126:Z132) -> 47 | AT21: =SUM(Z133:Z139) -> 111 | AU21: =SUM(Z140:Z149) -> 0 | AV21: =IFERROR(SUM(Z119:Z125)/COUNTIF(Y119:Y125,1),0) -> 13 | AW21: =IFERROR(SUM(Z126:Z132)/COUNTIF(Y126:Y132,1),0) -> 11.75 | AX21: =IFERROR(SUM(Z133:Z139)/COUNTIF(Y133:Y139,1),0) -> 27.75 | AY21: =IFERROR(SUM(Z140:Z149)/COUNTIF(Y140:Y149,1),0) -> 0 | AZ21: =3240 -> 3240 | BA21: =SUM(Z119:Z149) -> 223 | BB21: =IFERROR(BA21/AZ21,0) -> 0.06882716 | BC21: =SUM(AA119:AA149) -> 1226500 | BD21: =IFERROR(BA21/AP21,0) -> 17.153846 | BE21: =IFERROR(BF21/BC21,0) -> 1.9184884 | BF21: =BG21*AP21 -> 2353026 | BG21: 181002 | BH21: =IFERROR(MAX(AZ21-BA21,0)/24/MAX(AO21-AP21,1),0) -> 11.42803 | BI21: =IFERROR(MAX(AZ21-BA21,0)/MAX(AO21-AP21,1),0) -> 274.27273 | BJ21: =IFERROR(26*BG21/BM21,0) -> 15686840 | BK21: =MAX(BJ21-BC21,0) -> 14460340 | BL21: =BE21-BM21 -> 1.6184884 | BM21: 0.3 | BN21: =IFERROR(MAX(BP21-BA21,0)/MAX(AO21-AP21,1),0) -> 274.27273 | BO21: =BN21/24 -> 11.42803 | BP21: =3240 -> 3240 | BQ21: =MAX(BP21-BA21,0) -> 3017 | BR21: =BQ21/24 -> 125.70833 | BS21: 46175
S22: 46253 | X22: 46253 | AC22: 46253 | AH22: 46222 | AN22: Nurhijrah | AO22: 24 | AP22: =COUNTIF(AD119:AD149,1) -> 15 | AQ22: =IFERROR(AP22/AO22,0) -> 0.625 | AR22: =SUM(AE119:AE125) -> 183 | AS22: =SUM(AE126:AE132) -> 163 | AT22: =SUM(AE133:AE139) -> 129 | AU22: =SUM(AE140:AE149) -> 0 | AV22: =IFERROR(SUM(AE119:AE125)/COUNTIF(AD119:AD125,1),0) -> 30.5 | AW22: =IFERROR(SUM(AE126:AE132)/COUNTIF(AD126:AD132,1),0) -> 32.6 | AX22: =IFERROR(SUM(AE133:AE139)/COUNTIF(AD133:AD139,1),0) -> 32.25 | AY22: =IFERROR(SUM(AE140:AE149)/COUNTIF(AD140:AD149,1),0) -> 0 | AZ22: =3240 -> 3240 | BA22: =SUM(AE119:AE149) -> 475 | BB22: =IFERROR(BA22/AZ22,0) -> 0.14660494 | BC22: =SUM(AF119:AF149) -> 3063300 | BD22: =IFERROR(BA22/AP22,0) -> 31.666667 | BE22: =IFERROR(BF22/BC22,0) -> 0.88630888 | BF22: =BG22*AP22 -> 2715030 | BG22: 181002 | BH22: =IFERROR(MAX(AZ22-BA22,0)/24/MAX(AO22-AP22,1),0) -> 12.800926 | BI22: =IFERROR(MAX(AZ22-BA22,0)/MAX(AO22-AP22,1),0) -> 307.22222 | BJ22: =IFERROR(26*BG22/BM22,0) -> 15686840 | BK22: =MAX(BJ22-BC22,0) -> 12623540 | BL22: =BE22-BM22 -> 0.58630888 | BM22: 0.3 | BN22: =IFERROR(MAX(BP22-BA22,0)/MAX(AO22-AP22,1),0) -> 307.22222 | BO22: =BN22/24 -> 12.800926 | BP22: =3240 -> 3240 | BQ22: =MAX(BP22-BA22,0) -> 2765 | BR22: =BQ22/24 -> 115.20833 | BS22: 46235
H23: SELLING OUT BY MTD | K23: SELLING OUT BY MONTH | N23: SELLING OUT BY VALUE | S23: 46254 | X23: 46254 | AC23: 46254 | AH23: 46223 | AM23: GRAND TOTAL MAKASSAR | AO23: =SUM(AO20:AO22) -> 72 | AP23: =SUM(AP20:AP22) -> 44 | AQ23: =IFERROR(AP23/AO23,0) -> 0.61111111 | AR23: =SUM(AR20:AR22) -> 452 | AS23: =SUM(AS20:AS22) -> 361 | AT23: =SUM(AT20:AT22) -> 372 | AU23: =SUM(AU20:AU22) -> 0 | AV23: =IFERROR(AR23/(COUNTIF(T119:T125,1)+COUNTIF(Y119:Y125,1)+COUNTIF(AD119:AD125,1)),0) -> 26.588235 | AW23: =IFERROR(AS23/(COUNTIF(T126:T132,1)+COUNTIF(Y126:Y132,1)+COUNTIF(AD126:AD132,1)),0) -> 24.066667 | AX23: =IFERROR(AT23/(COUNTIF(T133:T139,1)+COUNTIF(Y133:Y139,1)+COUNTIF(AD133:AD139,1)),0) -> 31 | AY23: =IFERROR(AU23/(COUNTIF(T140:T149,1)+COUNTIF(Y140:Y149,1)+COUNTIF(AD140:AD149,1)),0) -> 0 | AZ23: =SUM(AZ20:AZ22) -> 9720 | BA23: =SUM(BA20:BA22) -> 1185 | BB23: =IFERROR(BA23/AZ23,0) -> 0.12191358 | BC23: =SUM(BC20:BC22) -> 7540800 | BD23: =IFERROR(BA23/AP23,0) -> 26.931818 | BE23: =IFERROR(BF23/BC23,0) -> 1.056133 | BF23: =SUM(BF20:BF22) -> 7964088 | BG23: 181002 | BH23: =IFERROR(MAX(AZ23-BA23,0)/24/MAX(AO23-AP23,1),0) -> 12.700893 | BI23: =IFERROR(MAX(AZ23-BA23,0)/MAX(AO23-AP23,1),0) -> 304.82143 | BJ23: =SUM(BJ20:BJ22) -> 47060520 | BK23: =MAX(BJ23-BC23,0) -> 39519720 | BL23: =BE23-BM23 -> 0.75613304 | BM23: 0.3 | BN23: =IFERROR(MAX(BP23-BA23,0)/MAX(AO23-AP23,1),0) -> 304.82143 | BO23: =BN23/24 -> 12.700893 | BP23: =SUM(BP20:BP22) -> 9720 | BQ23: =MAX(BP23-BA23,0) -> 8535 | BR23: =BQ23/24 -> 355.625
A24: REGION | B24: AREA | C24: NAMA TOKO | E24: NAMA SPG | F24: JOINT DATE | G24: HK | H24: TARGET BY HK | I24: ACTUAL BY HK | J24: ACV BY HK (%) | K24: TARGET BY MONTH | L24: ACTUAL BY MONTH | M24: ACV BY MONTH (%) | N24: TOTAL VALUE (Rp) | O24: AVRG PER DAY | S24: 46255 | X24: 46255 | AC24: 46255 | AH24: 46224 | AM24: MANADO | AN24: Dea | AO24: 24 | AP24: =COUNTIF(AD83:AD113,1) -> 13 | AQ24: =IFERROR(AP24/AO24,0) -> 0.54166667 | AR24: =SUM(AE83:AE89) -> 144 | AS24: =SUM(AE90:AE96) -> 174 | AT24: =SUM(AE97:AE103) -> 60 | AU24: =SUM(AE104:AE113) -> 0 | AV24: =IFERROR(SUM(AE83:AE89)/COUNTIF(AD83:AD89,1),0) -> 28.8 | AW24: =IFERROR(SUM(AE90:AE96)/COUNTIF(AD90:AD96,1),0) -> 29 | AX24: =IFERROR(SUM(AE97:AE103)/COUNTIF(AD97:AD103,1),0) -> 30 | AY24: =IFERROR(SUM(AE104:AE113)/COUNTIF(AD104:AD113,1),0) -> 0 | AZ24: =3240 -> 3240 | BA24: =SUM(AE83:AE113) -> 378 | BB24: =IFERROR(BA24/AZ24,0) -> 0.11666667 | BC24: =SUM(AF83:AF113) -> 2256000 | BD24: =IFERROR(BA24/AP24,0) -> 29.076923 | BE24: =IFERROR(BF24/BC24,0) -> 0.97121986 | BF24: =BG24*AP24 -> 2191072 | BG24: 168544 | BH24: =IFERROR(MAX(AZ24-BA24,0)/24/MAX(AO24-AP24,1),0) -> 10.840909 | BI24: =IFERROR(MAX(AZ24-BA24,0)/MAX(AO24-AP24,1),0) -> 260.18182 | BJ24: =IFERROR(26*BG24/BM24,0) -> 14607147 | BK24: =MAX(BJ24-BC24,0) -> 12351147 | BL24: =BE24-BM24 -> 0.67121986 | BM24: 0.3 | BN24: =IFERROR(MAX(BP24-BA24,0)/MAX(AO24-AP24,1),0) -> 260.18182 | BO24: =BN24/24 -> 10.840909 | BP24: =3240 -> 3240 | BQ24: =MAX(BP24-BA24,0) -> 2862 | BR24: =BQ24/24 -> 119.25 | BS24: 46157
S25: 46256 | X25: 46256 | AC25: 46256 | AH25: 46225 | AN25: Regina | AO25: 24 | AP25: =COUNTIF(AI83:AI113,1) -> 13 | AQ25: =IFERROR(AP25/AO25,0) -> 0.54166667 | AR25: =SUM(AJ83:AJ89) -> 177 | AS25: =SUM(AJ90:AJ96) -> 162 | AT25: =SUM(AJ97:AJ103) -> 35 | AU25: =SUM(AJ104:AJ113) -> 0 | AV25: =IFERROR(SUM(AJ83:AJ89)/COUNTIF(AI83:AI89,1),0) -> 29.5 | AW25: =IFERROR(SUM(AJ90:AJ96)/COUNTIF(AI90:AI96,1),0) -> 27 | AX25: =IFERROR(SUM(AK90:AK96)/COUNTIF(AJ90:AJ96,1),0) -> 0 | AY25: =IFERROR(SUM(AJ104:AJ113)/COUNTIF(AI104:AI113,1),0) -> 0 | AZ25: =3240 -> 3240 | BA25: =SUM(AJ83:AJ113) -> 374 | BB25: =IFERROR(BA25/AZ25,0) -> 0.1154321 | BC25: =SUM(AK83:AK113) -> 2244000 | BD25: =IFERROR(BA25/AP25,0) -> 28.769231 | BE25: =IFERROR(BF25/BC25,0) -> 0.97641355 | BF25: =BG25*AP25 -> 2191072 | BG25: 168544 | BH25: =IFERROR(MAX(AZ25-BA25,0)/24/MAX(AO25-AP25,1),0) -> 10.856061 | BI25: =IFERROR(MAX(AZ25-BA25,0)/MAX(AO25-AP25,1),0) -> 260.54545 | BJ25: =IFERROR(26*BG25/BM25,0) -> 14607147 | BK25: =MAX(BJ25-BC25,0) -> 12363147 | BL25: =BE25-BM25 -> 0.67641355 | BM25: 0.3 | BN25: =IFERROR(MAX(BP25-BA25,0)/MAX(AO25-AP25,1),0) -> 260.54545 | BO25: =BN25/24 -> 10.856061 | BP25: =3240 -> 3240 | BQ25: =MAX(BP25-BA25,0) -> 2866 | BR25: =BQ25/24 -> 119.41667 | BS25: 46188
A26: 4 | B26: Balikpapan | C26: Toko Perdana | E26: Rami | F26: 1 Juni 2026 | G26: =SUM(AI40:AI69) -> 14 | H26: =G26*120 -> 1680 | I26: =SUM(AJ40:AJ69) -> 672 | J26: =I26/H26 -> 0.4 | K26: 3240 | L26: =SUM(I26) -> 672 | M26: =L26/K26 -> 0.20740741 | N26: =SUM(AK40:AK70) -> 3952800 | O26: =I26/G26 -> 48 | S26: 46257 | X26: 46257 | AC26: 46257 | AH26: 46226 | AM26: GRAND TOTAL MANADO | AO26: =SUM(AO24:AO25) -> 48 | AP26: =SUM(AP24:AP25) -> 26 | AQ26: =IFERROR(AP26/AO26,0) -> 0.54166667 | AR26: =SUM(AR24:AR25) -> 321 | AS26: =SUM(AS24:AS25) -> 336 | AT26: =SUM(AT24:AT25) -> 95 | AU26: =SUM(AU24:AU25) -> 0 | AV26: =IFERROR(AR26/(COUNTIF(AD83:AD89,1)+COUNTIF(AI83:AI89,1)),0) -> 29.181818 | AW26: =IFERROR(AS26/(COUNTIF(AD90:AD96,1)+COUNTIF(AI90:AI96,1)),0) -> 28 | AX26: =IFERROR(AT26/(COUNTIF(AD97:AD103,1)+COUNTIF(AI97:AI103,1)),0) -> 31.666667 | AY26: =IFERROR(AU26/(COUNTIF(AD104:AD113,1)+COUNTIF(AI104:AI113,1)),0) -> 0 | AZ26: =SUM(AZ24:AZ25) -> 6480 | BA26: =SUM(BA24:BA25) -> 752 | BB26: =IFERROR(BA26/AZ26,0) -> 0.11604938 | BC26: =SUM(BC24:BC25) -> 4500000 | BD26: =IFERROR(BA26/AP26,0) -> 28.923077 | BE26: =IFERROR(BF26/BC26,0) -> 0.97380978 | BF26: =SUM(BF24:BF25) -> 4382144 | BG26: 168544 | BH26: =IFERROR(MAX(AZ26-BA26,0)/24/MAX(AO26-AP26,1),0) -> 10.848485 | BI26: =IFERROR(MAX(AZ26-BA26,0)/MAX(AO26-AP26,1),0) -> 260.36364 | BJ26: =SUM(BJ24:BJ25) -> 29214293 | BK26: =MAX(BJ26-BC26,0) -> 24714293 | BL26: =BE26-BM26 -> 0.67380978 | BM26: 0.3 | BN26: =IFERROR(MAX(BP26-BA26,0)/MAX(AO26-AP26,1),0) -> 260.36364 | BO26: =BN26/24 -> 10.848485 | BP26: =SUM(BP24:BP25) -> 6480 | BQ26: =MAX(BP26-BA26,0) -> 5728 | BR26: =BQ26/24 -> 238.66667
A27: 4 | B27: Balikpapan | C27: Toko Perdana | E27: Grace | F27: 1 Juli 2026 | G27: =SUM(AD40:AD69) -> 13 | H27: =G27*120 -> 1560 | I27: =SUM(AE40:AE71) -> 480 | J27: =I27/H27 -> 0.30769231 | K27: 3240 | L27: =SUM(I27) -> 480 | M27: =L27/K27 -> 0.14814815 | N27: =SUM(AF40:AF70) -> 2894400 | O27: =I27/G27 -> 36.923077 | S27: 46258 | X27: 46258 | AC27: 46258 | AH27: 46227 | AM27: GRAND TOTAL COVER | AO27: =SUM(AO10,AO13,AO16,AO19,AO23,AO26) -> 360 | AP27: =SUM(AP10,AP13,AP16,AP19,AP23,AP26) -> 191 | AQ27: =IFERROR(AP27/AO27,0) -> 0.53055556 | AR27: =SUM(AR10,AR13,AR16,AR19,AR23,AR26) -> 4621 | AS27: =SUM(AS10,AS13,AS16,AS19,AS23,AS26) -> 4408 | AT27: =SUM(AT10,AT13,AT16,AT19,AT23,AT26) -> 1691 | AU27: =SUM(AU10,AU13,AU16,AU19,AU23,AU26) -> 0 | AV27: =AVERAGE(AV10,AV13,AV16,AV19,AV23,AV26) -> 56.057992 | AW27: =AVERAGE(AW10,AW13,AW16,AW19,AW23,AW26) -> 54.141013 | AX27: =AVERAGE(AX10,AX13,AX16,AX19,AX23,AX26) -> 56.044444 | AY27: =AVERAGE(AY10,AY13,AY16,AY19,AY23,AY26) -> 0 | AZ27: =SUM(AZ10,AZ13,AZ16,AZ19,AZ23,AZ26) -> 48600 | BA27: =SUM(BA10,BA13,BA16,BA19,BA23,BA26) -> 10720 | BB27: =IFERROR(BA27/AZ27,0) -> 0.22057613 | BC27: =SUM(BC10,BC13,BC16,BC19,BC23,BC26) -> 65084000 | BD27: =IFERROR(BA27/AP27,0) -> 56.125654 | BE27: =IFERROR(BF27/BC27,0) -> 0.50518767 | BF27: =SUM(BF10,BF13,BF16,BF19,BF23,BF26) -> 32879634 | BH27: =IFERROR(MAX(AZ27-BA27,0)/24/MAX(AO27-AP27,1),0) -> 9.3392505 | BI27: =IFERROR(MAX(AZ27-BA27,0)/MAX(AO27-AP27,1),0) -> 224.14201 | BJ27: =SUM(BJ10,BJ13,BJ16,BJ19,BJ23,BJ26) -> 2.3309518e+08 | BK27: =MAX(BJ27-BC27,0) -> 1.6801118e+08 | BL27: =BE27-BM27 -> 0.21768619 | BM27: =((26*BG6)+(26*BG7)+(26*BG8)+(26*BG9)+(26*BG11)+(26*BG12)+(26*BG14)+(26*BG15)+(26*BG17)+(26*BG18)+(26*BG20)+(26*BG21)+(26*BG22)+(26*BG24)+(26*BG25))/BJ27 -> 0.28750147 | BN27: =IFERROR(MAX(BP27-BA27,0)/MAX(AO27-AP27,1),0) -> 224.14201 | BO27: =BN27/24 -> 9.3392505 | BP27: =SUM(BP10,BP13,BP16,BP19,BP23,BP26) -> 48600 | BQ27: =MAX(BP27-BA27,0) -> 37880 | BR27: =BQ27/24 -> 1578.3333
A28: TOTAL BALIKPAPAN | G28: =SUM(G26:G27) -> 27 | H28: =SUM(H26:H27) -> 3240 | I28: =SUM(I26:I27) -> 1152 | J28: =I28/H28 -> 0.35555556 | K28: =SUM(K26:K27) -> 6480 | L28: =SUM(L26:L27) -> 1152 | M28: =L28/K28 -> 0.17777778 | N28: =SUM(N26:N27) -> 6847200 | O28: =L28/G28 -> 42.666667 | S28: 46259 | X28: 46259 | AC28: 46259 | AH28: 46228
S29: 46260 | X29: 46260 | AC29: 46260 | AH29: 46229
H30: SELLING OUT BY MTD | K30: SELLING OUT BY MONTH | N30: SELLING OUT BY VALUE | S30: 46261 | X30: 46261 | AC30: 46261 | AH30: 46230
A31: REGION | B31: AREA | C31: NAMA TOKO | E31: NAMA SPG | F31: JOINT DATE | G31: HK | H31: TARGET BY HK | I31: ACTUAL BY HK | J31: ACV BY HK (%) | K31: TARGET BY MONTH | L31: ACTUAL BY MONTH | M31: ACV BY MONTH (%) | N31: TOTAL VALUE (Rp) | O31: AVRG PER DAY | S31: 46262 | X31: 46262 | AC31: 46262 | AH31: 46231
S32: 46263 | X32: 46263 | AC32: 46263 | AH32: 46232
A33: 4 | B33: Palangkaraya | C33: Toko Tanjung | E33: Fani Febriani | F33: 27 Desember 2025 | G33: =SUM(T83:T113) -> 14 | H33: =G33*120 -> 1680 | I33: =SUM(U83:U113) -> 935 | J33: =I33/H33 -> 0.55654762 | K33: 3240 | L33: =SUM(I33) -> 935 | M33: =L33/K33 -> 0.28858025 | N33: =SUM(V83:V112) -> 5368000 | O33: =L33/G33 -> 66.785714 | S33: 46264 | X33: 46264 | AC33: 46264 | AH33: 46233
A34: 4 | B34: Palangkaraya | C34: Toko H fathur | E34: Siska | F34: 8 April 2026 | G34: =SUM(Y83:Y113) -> 14 | H34: =G34*120 -> 1680 | I34: =SUM(Z83:Z113) -> 996 | J34: =I34/H34 -> 0.59285714 | K34: 3240 | L34: =SUM(I34) -> 996 | M34: =L34/K34 -> 0.30740741 | N34: =SUM(AA83:AA112) -> 5976000 | O34: =L34/G34 -> 71.142857 | S34: 46265 | X34: 46265 | AC34: 46265 | AH34: 46234
A35: TOTAL PALANGKARAYA | G35: =SUM(G33:G34) -> 28 | H35: =SUM(H33:H34) -> 3360 | I35: =SUM(I33:I34) -> 1931 | J35: =I35/H35 -> 0.57470238 | K35: =SUM(K33:K34) -> 6480 | L35: =SUM(L33:L34) -> 1931 | M35: =L35/K35 -> 0.29799383 | N35: =SUM(N33:N34) -> 11344000 | O35: =L35/G35 -> 68.964286
H37: SELLING OUT BY MTD | K37: SELLING OUT BY MONTH | N37: SELLING OUT BY VALUE | S37: AREA SAMARINDA | AC37: AREA BALIKPAPAN
A38: REGION | B38: AREA | C38: NAMA TOKO | E38: NAMA SPG | F38: JOINT DATE | G38: HK | H38: TARGET BY HK | I38: ACTUAL BY HK | J38: ACV BY HK (%) | K38: TARGET BY MONTH | L38: ACTUAL BY MONTH | M38: ACV BY MONTH (%) | N38: TOTAL VALUE (Rp) | O38: AVRG PER DAY | S38: FITRIANI (JOINT PER TANGGAL 7 FEBRUARI 2026) | X38: DESI SUSANTI (JOINT PER TANGGAL 20 FEBRUARI 2026) | AC38: GRACE (JOINT PER TANGGAL 1 JULI 2026) | AH38: RAMI (JOINT PER TANGGAL 1 JUNI 2026)
S39: Tanggal | T39: STATUS ABSENSI | U39: Selling (pcs) | V39: Value (Rp) | X39: Tanggal | Y39: STATUS ABSENSI | Z39: Selling (pcs) | AA39: Value (Rp) | AC39: Tanggal | AD39: STATUS ABSENSI | AE39: Selling (pcs) | AF39: Value (Rp) | AH39: Tanggal | AI39: STATUS ABSENSI | AJ39: Selling (pcs) | AK39: Value (Rp)
A40: 4 | B40: Samarinda | C40: Toko Alam Subur | E40: Fitriani | F40: 7 Februari 2026 | G40: =SUM(T40:T69) -> 13 | H40: =G40*120 -> 1560 | I40: =SUM(U40:U70) -> 864 | J40: =I40/H40 -> 0.55384615 | K40: 3240 | L40: =SUM(I40) -> 864 | M40: =L40/K40 -> 0.26666667 | N40: =SUM(V40:V69) -> 5616000 | O40: 93 | S40: 46235 | T40: OFF | X40: 46235 | Y40: 1 | AC40: 46235 | AD40: IZIN | AH40: 46235 | AI40: IZIN
A41: 4 | B41: Samarinda | C41: Toko Surya Indah | E41: Desi susanti | F41: 20 Februari 2026 | G41: =SUM(Y40:Y70) -> 14 | H41: =G41*96 -> 1344 | I41: =SUM(Z40:Z69) -> 816 | J41: =I41/H41 -> 0.60714286 | K41: 3240 | L41: =SUM(I41) -> 816 | M41: =L41/K41 -> 0.25185185 | N41: =SUM(AA40:AA69) -> 5112000 | O41: 85 | S41: 46236 | T41: OFF | X41: 46236 | Y41: OFF | AC41: 46236 | AD41: OFF | AH41: 46236 | AI41: OFF
...

Sheet HK
A1: PLANNING HK SPG AGUSTUS 2026 - POSISI 1-17 AGUSTUS
A2: Target 24 HK | 25 Agustus LIBUR | OFF Mingguan: semua SPG hari Minggu, Fani hari Senin, Siska hari Kamis
A4: AREA | B4: SPG | C4: HK ACTUAL 1-17 | D4: TARGET HK | E4: SISA HK | F4: 46252 | G4: 46253 | H4: 46254 | I4: 46255 | J4: 46256 | K4: 23/08/2026 (MINGGU) | L4: 46258 | M4: 46259 | N4: 46260 | O4: 46261 | P4: 46262 | Q4: 46263 | R4: 46264 | S4: 46265 | T4: PROYEKSI HK | U4: GAP HK | V4: STATUS
A5: Banjarmasin | B5: Nurul | C5: =COUNTIF('Daily Report & WIP'!T4:T20,1) -> 12 | D5: 24 | E5: =MAX(D5-C5,0) -> 12 | F5: =IF($E5>0,"KERJA","OFF TARGET") -> KERJA | G5: =IF(COUNTIF($F5:F5,"KERJA")<$E5,"KERJA","OFF TARGET") -> KERJA | H5: =IF(COUNTIF($F5:G5,"KERJA")<$E5,"KERJA","OFF TARGET") -> KERJA | I5: =IF(COUNTIF($F5:H5,"KERJA")<$E5,"KERJA","OFF TARGET") -> KERJA | J5: =IF(COUNTIF($F5:I5,"KERJA")<$E5,"KERJA","OFF TARGET") -> KERJA | K5: OFF | L5: =IF(COUNTIF($F5:K5,"KERJA")<$E5,"KERJA","OFF TARGET") -> KERJA | M5: LIBUR | N5: =IF(COUNTIF($F5:M5,"KERJA")<$E5,"KERJA","OFF TARGET") -> KERJA | O5: =IF(COUNTIF($F5:N5,"KERJA")<$E5,"KERJA","OFF TARGET") -> KERJA | P5: =IF(COUNTIF($F5:O5,"KERJA")<$E5,"KERJA","OFF TARGET") -> KERJA | Q5: =IF(COUNTIF($F5:P5,"KERJA")<$E5,"KERJA","OFF TARGET") -> KERJA | R5: OFF | S5: =IF(COUNTIF($F5:R5,"KERJA")<$E5,"KERJA","OFF TARGET") -> KERJA | T5: =C5+COUNTIF(F5:S5,"KERJA") -> 23 | U5: =D5-T5 -> 1 | V5: =IF(U5=0,"TARGET 24 HK TERCAPAI",IF(U5>0,"MASIH KURANG "&U5&" HK","LEBIH "&ABS(U5)&" HK")) -> MASIH KURANG 1 HK
A6: Banjarmasin | B6: Khoirunisa | C6: =COUNTIF('Daily Report & WIP'!Y4:Y20,1) -> 12 | D6: 24 | E6: =MAX(D6-C6,0) -> 12 | F6: =IF($E6>0,"KERJA","OFF TARGET") -> KERJA | G6: =IF(COUNTIF($F6:F6,"KERJA")<$E6,"KERJA","OFF TARGET") -> KERJA | H6: =IF(COUNTIF($F6:G6,"KERJA")<$E6,"KERJA","OFF TARGET") -> KERJA | I6: =IF(COUNTIF($F6:H6,"KERJA")<$E6,"KERJA","OFF TARGET") -> KERJA | J6: =IF(COUNTIF($F6:I6,"KERJA")<$E6,"KERJA","OFF TARGET") -> KERJA | K6: OFF | L6: =IF(COUNTIF($F6:K6,"KERJA")<$E6,"KERJA","OFF TARGET") -> KERJA | M6: LIBUR | N6: =IF(COUNTIF($F6:M6,"KERJA")<$E6,"KERJA","OFF TARGET") -> KERJA | O6: =IF(COUNTIF($F6:N6,"KERJA")<$E6,"KERJA","OFF TARGET") -> KERJA | P6: =IF(COUNTIF($F6:O6,"KERJA")<$E6,"KERJA","OFF TARGET") -> KERJA | Q6: =IF(COUNTIF($F6:P6,"KERJA")<$E6,"KERJA","OFF TARGET") -> KERJA | R6: OFF | S6: =IF(COUNTIF($F6:R6,"KERJA")<$E6,"KERJA","OFF TARGET") -> KERJA | T6: =C6+COUNTIF(F6:S6,"KERJA") -> 23 | U6: =D6-T6 -> 1 | V6: =IF(U6=0,"TARGET 24 HK TERCAPAI",IF(U6>0,"MASIH KURANG "&U6&" HK","LEBIH "&ABS(U6)&" HK")) -> MASIH KURANG 1 HK
A7: Banjarmasin | B7: Herlisa | C7: =COUNTIF('Daily Report & WIP'!AD4:AD20,1) -> 13 | D7: 24 | E7: =MAX(D7-C7,0) -> 11 | F7: =IF($E7>0,"KERJA","OFF TARGET") -> KERJA | G7: =IF(COUNTIF($F7:F7,"KERJA")<$E7,"KERJA","OFF TARGET") -> KERJA | H7: =IF(COUNTIF($F7:G7,"KERJA")<$E7,"KERJA","OFF TARGET") -> KERJA | I7: =IF(COUNTIF($F7:H7,"KERJA")<$E7,"KERJA","OFF TARGET") -> KERJA | J7: =IF(COUNTIF($F7:I7,"KERJA")<$E7,"KERJA","OFF TARGET") -> KERJA | K7: OFF | L7: =IF(COUNTIF($F7:K7,"KERJA")<$E7,"KERJA","OFF TARGET") -> KERJA | M7: LIBUR | N7: =IF(COUNTIF($F7:M7,"KERJA")<$E7,"KERJA","OFF TARGET") -> KERJA | O7: =IF(COUNTIF($F7:N7,"KERJA")<$E7,"KERJA","OFF TARGET") -> KERJA | P7: =IF(COUNTIF($F7:O7,"KERJA")<$E7,"KERJA","OFF TARGET") -> KERJA | Q7: =IF(COUNTIF($F7:P7,"KERJA")<$E7,"KERJA","OFF TARGET") -> KERJA | R7: OFF | S7: =IF(COUNTIF($F7:R7,"KERJA")<$E7,"KERJA","OFF TARGET") -> KERJA | T7: =C7+COUNTIF(F7:S7,"KERJA") -> 24 | U7: =D7-T7 -> 0 | V7: =IF(U7=0,"TARGET 24 HK TERCAPAI",IF(U7>0,"MASIH KURANG "&U7&" HK","LEBIH "&ABS(U7)&" HK")) -> TARGET 24 HK TERCAPAI
A8: Banjarmasin | B8: Nur | C8: =COUNTIF('Daily Report & WIP'!AI4:AI20,1) -> 2 | D8: 24 | E8: =MAX(D8-C8,0) -> 22 | F8: =IF($E8>0,"KERJA","OFF TARGET") -> KERJA | G8: =IF(COUNTIF($F8:F8,"KERJA")<$E8,"KERJA","OFF TARGET") -> KERJA | H8: =IF(COUNTIF($F8:G8,"KERJA")<$E8,"KERJA","OFF TARGET") -> KERJA | I8: =IF(COUNTIF($F8:H8,"KERJA")<$E8,"KERJA","OFF TARGET") -> KERJA | J8: =IF(COUNTIF($F8:I8,"KERJA")<$E8,"KERJA","OFF TARGET") -> KERJA | K8: OFF | L8: =IF(COUNTIF($F8:K8,"KERJA")<$E8,"KERJA","OFF TARGET") -> KERJA | M8: LIBUR | N8: =IF(COUNTIF($F8:M8,"KERJA")<$E8,"KERJA","OFF TARGET") -> KERJA | O8: =IF(COUNTIF($F8:N8,"KERJA")<$E8,"KERJA","OFF TARGET") -> KERJA | P8: =IF(COUNTIF($F8:O8,"KERJA")<$E8,"KERJA","OFF TARGET") -> KERJA | Q8: =IF(COUNTIF($F8:P8,"KERJA")<$E8,"KERJA","OFF TARGET") -> KERJA | R8: OFF | S8: =IF(COUNTIF($F8:R8,"KERJA")<$E8,"KERJA","OFF TARGET") -> KERJA | T8: =C8+COUNTIF(F8:S8,"KERJA") -> 13 | U8: =D8-T8 -> 11 | V8: =IF(U8=0,"TARGET 24 HK TERCAPAI",IF(U8>0,"MASIH KURANG "&U8&" HK","LEBIH "&ABS(U8)&" HK")) -> MASIH KURANG 11 HK
A9: Balikpapan | B9: Grace | C9: =COUNTIF('Daily Report & WIP'!AD40:AD56,1) -> 12 | D9: 24 | E9: =MAX(D9-C9,0) -> 12 | F9: =IF($E9>0,"KERJA","OFF TARGET") -> KERJA | G9: =IF(COUNTIF($F9:F9,"KERJA")<$E9,"KERJA","OFF TARGET") -> KERJA | H9: =IF(COUNTIF($F9:G9,"KERJA")<$E9,"KERJA","OFF TARGET") -> KERJA | I9: =IF(COUNTIF($F9:H9,"KERJA")<$E9,"KERJA","OFF TARGET") -> KERJA | J9: =IF(COUNTIF($F9:I9,"KERJA")<$E9,"KERJA","OFF TARGET") -> KERJA | K9: OFF | L9: =IF(COUNTIF($F9:K9,"KERJA")<$E9,"KERJA","OFF TARGET") -> KERJA | M9: LIBUR | N9: =IF(COUNTIF($F9:M9,"KERJA")<$E9,"KERJA","OFF TARGET") -> KERJA | O9: =IF(COUNTIF($F9:N9,"KERJA")<$E9,"KERJA","OFF TARGET") -> KERJA | P9: =IF(COUNTIF($F9:O9,"KERJA")<$E9,"KERJA","OFF TARGET") -> KERJA | Q9: =IF(COUNTIF($F9:P9,"KERJA")<$E9,"KERJA","OFF TARGET") -> KERJA | R9: OFF | S9: =IF(COUNTIF($F9:R9,"KERJA")<$E9,"KERJA","OFF TARGET") -> KERJA | T9: =C9+COUNTIF(F9:S9,"KERJA") -> 23 | U9: =D9-T9 -> 1 | V9: =IF(U9=0,"TARGET 24 HK TERCAPAI",IF(U9>0,"MASIH KURANG "&U9&" HK","LEBIH "&ABS(U9)&" HK")) -> MASIH KURANG 1 HK
A10: Balikpapan | B10: Rami | C10: =COUNTIF('Daily Report & WIP'!AI40:AI56,1) -> 13 | D10: 24 | E10: =MAX(D10-C10,0) -> 11 | F10: =IF($E10>0,"KERJA","OFF TARGET") -> KERJA | G10: =IF(COUNTIF($F10:F10,"KERJA")<$E10,"KERJA","OFF TARGET") -> KERJA | H10: =IF(COUNTIF($F10:G10,"KERJA")<$E10,"KERJA","OFF TARGET") -> KERJA | I10: =IF(COUNTIF($F10:H10,"KERJA")<$E10,"KERJA","OFF TARGET") -> KERJA | J10: =IF(COUNTIF($F10:I10,"KERJA")<$E10,"KERJA","OFF TARGET") -> KERJA | K10: OFF | L10: =IF(COUNTIF($F10:K10,"KERJA")<$E10,"KERJA","OFF TARGET") -> KERJA | M10: LIBUR | N10: =IF(COUNTIF($F10:M10,"KERJA")<$E10,"KERJA","OFF TARGET") -> KERJA | O10: =IF(COUNTIF($F10:N10,"KERJA")<$E10,"KERJA","OFF TARGET") -> KERJA | P10: =IF(COUNTIF($F10:O10,"KERJA")<$E10,"KERJA","OFF TARGET") -> KERJA | Q10: =IF(COUNTIF($F10:P10,"KERJA")<$E10,"KERJA","OFF TARGET") -> KERJA | R10: OFF | S10: =IF(COUNTIF($F10:R10,"KERJA")<$E10,"KERJA","OFF TARGET") -> KERJA | T10: =C10+COUNTIF(F10:S10,"KERJA") -> 24 | U10: =D10-T10 -> 0 | V10: =IF(U10=0,"TARGET 24 HK TERCAPAI",IF(U10>0,"MASIH KURANG "&U10&" HK","LEBIH "&ABS(U10)&" HK")) -> TARGET 24 HK TERCAPAI
A11: Palangkaraya | B11: Fani Febriani | C11: =COUNTIF('Daily Report & WIP'!T83:T99,1) -> 14 | D11: 24 | E11: =MAX(D11-C11,0) -> 10 | F11: =IF($E11>0,"KERJA","OFF TARGET") -> KERJA | G11: =IF(COUNTIF($F11:F11,"KERJA")<$E11,"KERJA","OFF TARGET") -> KERJA | H11: =IF(COUNTIF($F11:G11,"KERJA")<$E11,"KERJA","OFF TARGET") -> KERJA | I11: =IF(COUNTIF($F11:H11,"KERJA")<$E11,"KERJA","OFF TARGET") -> KERJA | J11: =IF(COUNTIF($F11:I11,"KERJA")<$E11,"KERJA","OFF TARGET") -> KERJA | K11: =IF(COUNTIF($F11:J11,"KERJA")<$E11,"KERJA","OFF TARGET") -> KERJA | L11: OFF | M11: LIBUR | N11: =IF(COUNTIF($F11:M11,"KERJA")<$E11,"KERJA","OFF TARGET") -> KERJA | O11: =IF(COUNTIF($F11:N11,"KERJA")<$E11,"KERJA","OFF TARGET") -> KERJA | P11: =IF(COUNTIF($F11:O11,"KERJA")<$E11,"KERJA","OFF TARGET") -> KERJA | Q11: =IF(COUNTIF($F11:P11,"KERJA")<$E11,"KERJA","OFF TARGET") -> KERJA | R11: =IF(COUNTIF($F11:Q11,"KERJA")<$E11,"KERJA","OFF TARGET") -> OFF TARGET | S11: OFF | T11: =C11+COUNTIF(F11:S11,"KERJA") -> 24 | U11: =D11-T11 -> 0 | V11: =IF(U11=0,"TARGET 24 HK TERCAPAI",IF(U11>0,"MASIH KURANG "&U11&" HK","LEBIH "&ABS(U11)&" HK")) -> TARGET 24 HK TERCAPAI
A12: Palangkaraya | B12: Siska | C12: =COUNTIF('Daily Report & WIP'!Y83:Y99,1) -> 14 | D12: 24 | E12: =MAX(D12-C12,0) -> 10 | F12: =IF($E12>0,"KERJA","OFF TARGET") -> KERJA | G12: =IF(COUNTIF($F12:F12,"KERJA")<$E12,"KERJA","OFF TARGET") -> KERJA | H12: OFF | I12: =IF(COUNTIF($F12:H12,"KERJA")<$E12,"KERJA","OFF TARGET") -> KERJA | J12: =IF(COUNTIF($F12:I12,"KERJA")<$E12,"KERJA","OFF TARGET") -> KERJA | K12: =IF(COUNTIF($F12:J12,"KERJA")<$E12,"KERJA","OFF TARGET") -> KERJA | L12: =IF(COUNTIF($F12:K12,"KERJA")<$E12,"KERJA","OFF TARGET") -> KERJA | M12: LIBUR | N12: =IF(COUNTIF($F12:M12,"KERJA")<$E12,"KERJA","OFF TARGET") -> KERJA | O12: OFF | P12: =IF(COUNTIF($F12:O12,"KERJA")<$E12,"KERJA","OFF TARGET") -> KERJA | Q12: =IF(COUNTIF($F12:P12,"KERJA")<$E12,"KERJA","OFF TARGET") -> KERJA | R12: =IF(COUNTIF($F12:Q12,"KERJA")<$E12,"KERJA","OFF TARGET") -> KERJA | S12: =IF(COUNTIF($F12:R12,"KERJA")<$E12,"KERJA","OFF TARGET") -> OFF TARGET | T12: =C12+COUNTIF(F12:S12,"KERJA") -> 24 | U12: =D12-T12 -> 0 | V12: =IF(U12=0,"TARGET 24 HK TERCAPAI",IF(U12>0,"MASIH KURANG "&U12&" HK","LEBIH "&ABS(U12)&" HK")) -> TARGET 24 HK TERCAPAI
A13: Samarinda | B13: Fitriani | C13: =COUNTIF('Daily Report & WIP'!T40:T56,1) -> 12 | D13: 24 | E13: =MAX(D13-C13,0) -> 12 | F13: =IF($E13>0,"KERJA","OFF TARGET") -> KERJA | G13: =IF(COUNTIF($F13:F13,"KERJA")<$E13,"KERJA","OFF TARGET") -> KERJA | H13: =IF(COUNTIF($F13:G13,"KERJA")<$E13,"KERJA","OFF TARGET") -> KERJA | I13: =IF(COUNTIF($F13:H13,"KERJA")<$E13,"KERJA","OFF TARGET") -> KERJA | J13: =IF(COUNTIF($F13:I13,"KERJA")<$E13,"KERJA","OFF TARGET") -> KERJA | K13: OFF | L13: =IF(COUNTIF($F13:K13,"KERJA")<$E13,"KERJA","OFF TARGET") -> KERJA | M13: LIBUR | N13: =IF(COUNTIF($F13:M13,"KERJA")<$E13,"KERJA","OFF TARGET") -> KERJA | O13: =IF(COUNTIF($F13:N13,"KERJA")<$E13,"KERJA","OFF TARGET") -> KERJA | P13: =IF(COUNTIF($F13:O13,"KERJA")<$E13,"KERJA","OFF TARGET") -> KERJA | Q13: =IF(COUNTIF($F13:P13,"KERJA")<$E13,"KERJA","OFF TARGET") -> KERJA | R13: OFF | S13: =IF(COUNTIF($F13:R13,"KERJA")<$E13,"KERJA","OFF TARGET") -> KERJA | T13: =C13+COUNTIF(F13:S13,"KERJA") -> 23 | U13: =D13-T13 -> 1 | V13: =IF(U13=0,"TARGET 24 HK TERCAPAI",IF(U13>0,"MASIH KURANG "&U13&" HK","LEBIH "&ABS(U13)&" HK")) -> MASIH KURANG 1 HK
A14: Samarinda | B14: Desi Susanti | C14: =COUNTIF('Daily Report & WIP'!Y40:Y56,1) -> 13 | D14: 24 | E14: =MAX(D14-C14,0) -> 11 | F14: =IF($E14>0,"KERJA","OFF TARGET") -> KERJA | G14: =IF(COUNTIF($F14:F14,"KERJA")<$E14,"KERJA","OFF TARGET") -> KERJA | H14: =IF(COUNTIF($F14:G14,"KERJA")<$E14,"KERJA","OFF TARGET") -> KERJA | I14: =IF(COUNTIF($F14:H14,"KERJA")<$E14,"KERJA","OFF TARGET") -> KERJA | J14: =IF(COUNTIF($F14:I14,"KERJA")<$E14,"KERJA","OFF TARGET") -> KERJA | K14: OFF | L14: =IF(COUNTIF($F14:K14,"KERJA")<$E14,"KERJA","OFF TARGET") -> KERJA | M14: LIBUR | N14: =IF(COUNTIF($F14:M14,"KERJA")<$E14,"KERJA","OFF TARGET") -> KERJA | O14: =IF(COUNTIF($F14:N14,"KERJA")<$E14,"KERJA","OFF TARGET") -> KERJA | P14: =IF(COUNTIF($F14:O14,"KERJA")<$E14,"KERJA","OFF TARGET") -> KERJA | Q14: =IF(COUNTIF($F14:P14,"KERJA")<$E14,"KERJA","OFF TARGET") -> KERJA | R14: OFF | S14: =IF(COUNTIF($F14:R14,"KERJA")<$E14,"KERJA","OFF TARGET") -> KERJA | T14: =C14+COUNTIF(F14:S14,"KERJA") -> 24 | U14: =D14-T14 -> 0 | V14: =IF(U14=0,"TARGET 24 HK TERCAPAI",IF(U14>0,"MASIH KURANG "&U14&" HK","LEBIH "&ABS(U14)&" HK")) -> TARGET 24 HK TERCAPAI
A15: Makassar | B15: Amelia | C15: =COUNTIF('Daily Report & WIP'!T119:T135,1) -> 14 | D15: 24 | E15: =MAX(D15-C15,0) -> 10 | F15: =IF($E15>0,"KERJA","OFF TARGET") -> KERJA | G15: =IF(COUNTIF($F15:F15,"KERJA")<$E15,"KERJA","OFF TARGET") -> KERJA | H15: =IF(COUNTIF($F15:G15,"KERJA")<$E15,"KERJA","OFF TARGET") -> KERJA | I15: =IF(COUNTIF($F15:H15,"KERJA")<$E15,"KERJA","OFF TARGET") -> KERJA | J15: =IF(COUNTIF($F15:I15,"KERJA")<$E15,"KERJA","OFF TARGET") -> KERJA | K15: OFF | L15: =IF(COUNTIF($F15:K15,"KERJA")<$E15,"KERJA","OFF TARGET") -> KERJA | M15: LIBUR | N15: =IF(COUNTIF($F15:M15,"KERJA")<$E15,"KERJA","OFF TARGET") -> KERJA | O15: =IF(COUNTIF($F15:N15,"KERJA")<$E15,"KERJA","OFF TARGET") -> KERJA | P15: =IF(COUNTIF($F15:O15,"KERJA")<$E15,"KERJA","OFF TARGET") -> KERJA | Q15: =IF(COUNTIF($F15:P15,"KERJA")<$E15,"KERJA","OFF TARGET") -> KERJA | R15: OFF | S15: =IF(COUNTIF($F15:R15,"KERJA")<$E15,"KERJA","OFF TARGET") -> OFF TARGET | T15: =C15+COUNTIF(F15:S15,"KERJA") -> 24 | U15: =D15-T15 -> 0 | V15: =IF(U15=0,"TARGET 24 HK TERCAPAI",IF(U15>0,"MASIH KURANG "&U15&" HK","LEBIH "&ABS(U15)&" HK")) -> TARGET 24 HK TERCAPAI
A16: Makassar | B16: Dira/Nadira | C16: =COUNTIF('Daily Report & WIP'!Y119:Y135,1) -> 11 | D16: 24 | E16: =MAX(D16-C16,0) -> 13 | F16: =IF($E16>0,"KERJA","OFF TARGET") -> KERJA | G16: =IF(COUNTIF($F16:F16,"KERJA")<$E16,"KERJA","OFF TARGET") -> KERJA | H16: =IF(COUNTIF($F16:G16,"KERJA")<$E16,"KERJA","OFF TARGET") -> KERJA | I16: =IF(COUNTIF($F16:H16,"KERJA")<$E16,"KERJA","OFF TARGET") -> KERJA | J16: =IF(COUNTIF($F16:I16,"KERJA")<$E16,"KERJA","OFF TARGET") -> KERJA | K16: OFF | L16: =IF(COUNTIF($F16:K16,"KERJA")<$E16,"KERJA","OFF TARGET") -> KERJA | M16: LIBUR | N16: =IF(COUNTIF($F16:M16,"KERJA")<$E16,"KERJA","OFF TARGET") -> KERJA | O16: =IF(COUNTIF($F16:N16,"KERJA")<$E16,"KERJA","OFF TARGET") -> KERJA | P16: =IF(COUNTIF($F16:O16,"KERJA")<$E16,"KERJA","OFF TARGET") -> KERJA | Q16: =IF(COUNTIF($F16:P16,"KERJA")<$E16,"KERJA","OFF TARGET") -> KERJA | R16: OFF | S16: =IF(COUNTIF($F16:R16,"KERJA")<$E16,"KERJA","OFF TARGET") -> KERJA | T16: =C16+COUNTIF(F16:S16,"KERJA") -> 22 | U16: =D16-T16 -> 2 | V16: =IF(U16=0,"TARGET 24 HK TERCAPAI",IF(U16>0,"MASIH KURANG "&U16&" HK","LEBIH "&ABS(U16)&" HK")) -> MASIH KURANG 2 HK
A17: Makassar | B17: Nurhijrah | C17: =COUNTIF('Daily Report & WIP'!AD119:AD135,1) -> 13 | D17: 24 | E17: =MAX(D17-C17,0) -> 11 | F17: =IF($E17>0,"KERJA","OFF TARGET") -> KERJA | G17: =IF(COUNTIF($F17:F17,"KERJA")<$E17,"KERJA","OFF TARGET") -> KERJA | H17: =IF(COUNTIF($F17:G17,"KERJA")<$E17,"KERJA","OFF TARGET") -> KERJA | I17: =IF(COUNTIF($F17:H17,"KERJA")<$E17,"KERJA","OFF TARGET") -> KERJA | J17: =IF(COUNTIF($F17:I17,"KERJA")<$E17,"KERJA","OFF TARGET") -> KERJA | K17: OFF | L17: =IF(COUNTIF($F17:K17,"KERJA")<$E17,"KERJA","OFF TARGET") -> KERJA | M17: LIBUR | N17: =IF(COUNTIF($F17:M17,"KERJA")<$E17,"KERJA","OFF TARGET") -> KERJA | O17: =IF(COUNTIF($F17:N17,"KERJA")<$E17,"KERJA","OFF TARGET") -> KERJA | P17: =IF(COUNTIF($F17:O17,"KERJA")<$E17,"KERJA","OFF TARGET") -> KERJA | Q17: =IF(COUNTIF($F17:P17,"KERJA")<$E17,"KERJA","OFF TARGET") -> KERJA | R17: OFF | S17: =IF(COUNTIF($F17:R17,"KERJA")<$E17,"KERJA","OFF TARGET") -> KERJA | T17: =C17+COUNTIF(F17:S17,"KERJA") -> 24 | U17: =D17-T17 -> 0 | V17: =IF(U17=0,"TARGET 24 HK TERCAPAI",IF(U17>0,"MASIH KURANG "&U17&" HK","LEBIH "&ABS(U17)&" HK")) -> TARGET 24 HK TERCAPAI
A18: Manado | B18: Dea | C18: =COUNTIF('Daily Report & WIP'!AD83:AD99,1) -> 12 | D18: 24 | E18: =MAX(D18-C18,0) -> 12 | F18: =IF($E18>0,"KERJA","OFF TARGET") -> KERJA | G18: =IF(COUNTIF($F18:F18,"KERJA")<$E18,"KERJA","OFF TARGET") -> KERJA | H18: =IF(COUNTIF($F18:G18,"KERJA")<$E18,"KERJA","OFF TARGET") -> KERJA | I18: =IF(COUNTIF($F18:H18,"KERJA")<$E18,"KERJA","OFF TARGET") -> KERJA | J18: =IF(COUNTIF($F18:I18,"KERJA")<$E18,"KERJA","OFF TARGET") -> KERJA | K18: OFF | L18: =IF(COUNTIF($F18:K18,"KERJA")<$E18,"KERJA","OFF TARGET") -> KERJA | M18: LIBUR | N18: =IF(COUNTIF($F18:M18,"KERJA")<$E18,"KERJA","OFF TARGET") -> KERJA | O18: =IF(COUNTIF($F18:N18,"KERJA")<$E18,"KERJA","OFF TARGET") -> KERJA | P18: =IF(COUNTIF($F18:O18,"KERJA")<$E18,"KERJA","OFF TARGET") -> KERJA | Q18: =IF(COUNTIF($F18:P18,"KERJA")<$E18,"KERJA","OFF TARGET") -> KERJA | R18: OFF | S18: =IF(COUNTIF($F18:R18,"KERJA")<$E18,"KERJA","OFF TARGET") -> KERJA | T18: =C18+COUNTIF(F18:S18,"KERJA") -> 23 | U18: =D18-T18 -> 1 | V18: =IF(U18=0,"TARGET 24 HK TERCAPAI",IF(U18>0,"MASIH KURANG "&U18&" HK","LEBIH "&ABS(U18)&" HK")) -> MASIH KURANG 1 HK
A19: Manado | B19: Regina | C19: =COUNTIF('Daily Report & WIP'!AI83:AI99,1) -> 13 | D19: 24 | E19: =MAX(D19-C19,0) -> 11 | F19: =IF($E19>0,"KERJA","OFF TARGET") -> KERJA | G19: =IF(COUNTIF($F19:F19,"KERJA")<$E19,"KERJA","OFF TARGET") -> KERJA | H19: =IF(COUNTIF($F19:G19,"KERJA")<$E19,"KERJA","OFF TARGET") -> KERJA | I19: =IF(COUNTIF($F19:H19,"KERJA")<$E19,"KERJA","OFF TARGET") -> KERJA | J19: =IF(COUNTIF($F19:I19,"KERJA")<$E19,"KERJA","OFF TARGET") -> KERJA | K19: OFF | L19: =IF(COUNTIF($F19:K19,"KERJA")<$E19,"KERJA","OFF TARGET") -> KERJA | M19: LIBUR | N19: =IF(COUNTIF($F19:M19,"KERJA")<$E19,"KERJA","OFF TARGET") -> KERJA | O19: =IF(COUNTIF($F19:N19,"KERJA")<$E19,"KERJA","OFF TARGET") -> KERJA | P19: =IF(COUNTIF($F19:O19,"KERJA")<$E19,"KERJA","OFF TARGET") -> KERJA | Q19: =IF(COUNTIF($F19:P19,"KERJA")<$E19,"KERJA","OFF TARGET") -> KERJA | R19: OFF | S19: =IF(COUNTIF($F19:R19,"KERJA")<$E19,"KERJA","OFF TARGET") -> KERJA | T19: =C19+COUNTIF(F19:S19,"KERJA") -> 24 | U19: =D19-T19 -> 0 | V19: =IF(U19=0,"TARGET 24 HK TERCAPAI",IF(U19>0,"MASIH KURANG "&U19&" HK","LEBIH "&ABS(U19)&" HK")) -> TARGET 24 HK TERCAPAI

Sheet ZONA SPG
A1: ZONA SPG AGUSTUS 2026 - UPDATE 1-17 AGUSTUS
A3: AREA | B3: SPG | C3: HK ACTUAL | D3: TARGET HK | E3: ACHIEVEMENT | F3: RATIO | G3: KOMITMEN RATIO | H3: GAP KARTON/HARI | I3: ZONA | J3: STATUS TARGET
A4: Banjarmasin | B4: Nurul | C4: ='Daily Report & WIP'!AP6 -> 12 | D4: ='Daily Report & WIP'!AO6 -> 24 | E4: ='Daily Report & WIP'!BB6 -> 0.25185185 | F4: ='Daily Report & WIP'!BE6 -> 0.41607843 | G4: ='Daily Report & WIP'!BM6 -> 0.27 | H4: ='Daily Report & WIP'!BH6 -> 8.4166667 | I4: =IF(OR(F4>G4+5%,H4>8),"MERAH",IF(OR(F4>G4,H4>5),"KUNING","HIJAU")) -> MERAH | J4: =IF(E4>=1,"TERCAPAI","KEJAR TARGET") -> KEJAR TARGET
A5: Banjarmasin | B5: Khoirunisa | C5: ='Daily Report & WIP'!AP7 -> 12 | D5: ='Daily Report & WIP'!AO7 -> 24 | E5: ='Daily Report & WIP'!BB7 -> 0.47407407 | F5: ='Daily Report & WIP'!BE7 -> 0.2215224 | G5: ='Daily Report & WIP'!BM7 -> 0.27 | H5: ='Daily Report & WIP'!BH7 -> 5.9166667 | I5: =IF(OR(F5>G5+5%,H5>8),"MERAH",IF(OR(F5>G5,H5>5),"KUNING","HIJAU")) -> KUNING | J5: =IF(E5>=1,"TERCAPAI","KEJAR TARGET") -> KEJAR TARGET
A6: Banjarmasin | B6: Herlisa | C6: ='Daily Report & WIP'!AP8 -> 13 | D6: ='Daily Report & WIP'!AO8 -> 24 | E6: ='Daily Report & WIP'!BB8 -> 0.39259259 | F6: ='Daily Report & WIP'!BE8 -> 0.28916143 | G6: ='Daily Report & WIP'!BM8 -> 0.27 | H6: ='Daily Report & WIP'!BH8 -> 7.4545455 | I6: =IF(OR(F6>G6+5%,H6>8),"MERAH",IF(OR(F6>G6,H6>5),"KUNING","HIJAU")) -> KUNING | J6: =IF(E6>=1,"TERCAPAI","KEJAR TARGET") -> KEJAR TARGET
A7: Banjarmasin | B7: Nur | C7: ='Daily Report & WIP'!AP9 -> 2 | D7: ='Daily Report & WIP'!AO9 -> 24 | E7: ='Daily Report & WIP'!BB9 -> 0.12222222 | F7: ='Daily Report & WIP'!BE9 -> 0.14146667 | G7: ='Daily Report & WIP'!BM9 -> 0.27 | H7: ='Daily Report & WIP'!BH9 -> 5.3863636 | I7: =IF(OR(F7>G7+5%,H7>8),"MERAH",IF(OR(F7>G7,H7>5),"KUNING","HIJAU")) -> KUNING | J7: =IF(E7>=1,"TERCAPAI","KEJAR TARGET") -> KEJAR TARGET
A8: Balikpapan | B8: Grace | C8: ='Daily Report & WIP'!AP11 -> 13 | D8: ='Daily Report & WIP'!AO11 -> 24 | E8: ='Daily Report & WIP'!BB11 -> 0.14814815 | F8: ='Daily Report & WIP'!BE11 -> 0.76260468 | G8: ='Daily Report & WIP'!BM11 -> 0.3 | H8: ='Daily Report & WIP'!BH11 -> 10.454545 | I8: =IF(OR(F8>G8+5%,H8>8),"MERAH",IF(OR(F8>G8,H8>5),"KUNING","HIJAU")) -> MERAH | J8: =IF(E8>=1,"TERCAPAI","KEJAR TARGET") -> KEJAR TARGET
A9: Balikpapan | B9: Rami | C9: ='Daily Report & WIP'!AP12 -> 14 | D9: ='Daily Report & WIP'!AO12 -> 24 | E9: ='Daily Report & WIP'!BB12 -> 0.20740741 | F9: ='Daily Report & WIP'!BE12 -> 0.6013646 | G9: ='Daily Report & WIP'!BM12 -> 0.3 | H9: ='Daily Report & WIP'!BH12 -> 10.7 | I9: =IF(OR(F9>G9+5%,H9>8),"MERAH",IF(OR(F9>G9,H9>5),"KUNING","HIJAU")) -> MERAH | J9: =IF(E9>=1,"TERCAPAI","KEJAR TARGET") -> KEJAR TARGET
A10: Palangkaraya | B10: Fani Febriani | C10: ='Daily Report & WIP'!AP14 -> 14 | D10: ='Daily Report & WIP'!AO14 -> 24 | E10: ='Daily Report & WIP'!BB14 -> 0.28858025 | F10: ='Daily Report & WIP'!BE14 -> 0.42957936 | G10: ='Daily Report & WIP'!BM14 -> 0.27 | H10: ='Daily Report & WIP'!BH14 -> 9.6041667 | I10: =IF(OR(F10>G10+5%,H10>8),"MERAH",IF(OR(F10>G10,H10>5),"KUNING","HIJAU")) -> MERAH | J10: =IF(E10>=1,"TERCAPAI","KEJAR TARGET") -> KEJAR TARGET
A11: Palangkaraya | B11: Siska | C11: ='Daily Report & WIP'!AP15 -> 14 | D11: ='Daily Report & WIP'!AO15 -> 24 | E11: ='Daily Report & WIP'!BB15 -> 0.30740741 | F11: ='Daily Report & WIP'!BE15 -> 0.38587383 | G11: ='Daily Report & WIP'!BM15 -> 0.27 | H11: ='Daily Report & WIP'!BH15 -> 9.35 | I11: =IF(OR(F11>G11+5%,H11>8),"MERAH",IF(OR(F11>G11,H11>5),"KUNING","HIJAU")) -> MERAH | J11: =IF(E11>=1,"TERCAPAI","KEJAR TARGET") -> KEJAR TARGET
A12: Samarinda | B12: Fitriani | C12: ='Daily Report & WIP'!AP17 -> 13 | D12: ='Daily Report & WIP'!AO17 -> 24 | E12: ='Daily Report & WIP'!BB17 -> 0.26666667 | F12: ='Daily Report & WIP'!BE17 -> 0.4043588 | G12: ='Daily Report & WIP'!BM17 -> 0.3 | H12: ='Daily Report & WIP'!BH17 -> 9 | I12: =IF(OR(F12>G12+5%,H12>8),"MERAH",IF(OR(F12>G12,H12>5),"KUNING","HIJAU")) -> MERAH | J12: =IF(E12>=1,"TERCAPAI","KEJAR TARGET") -> KEJAR TARGET
B13: Desi Susanti | C13: ='Daily Report & WIP'!AP18 -> 14 | D13: ='Daily Report & WIP'!AO18 -> 24 | E13: ='Daily Report & WIP'!BB18 -> 0.25185185 | F13: ='Daily Report & WIP'!BE18 -> 0.47839632 | G13: ='Daily Report & WIP'!BM18 -> 0.3 | H13: ='Daily Report & WIP'!BH18 -> 10.1 | I13: =IF(OR(F13>G13+5%,H13>8),"MERAH",IF(OR(F13>G13,H13>5),"KUNING","HIJAU")) -> MERAH | J13: =IF(E13>=1,"TERCAPAI","KEJAR TARGET") -> KEJAR TARGET
